Workbook
Name Currency: '[1]Fixed&Misc Charges-Assumptions'!$K$2:$K$6
Name kk: '[1]Master FG'!$B$2:$B$172
Name Slicer_MC_ROUTING: #N/A
Name Slicer_MC_ROUTING1: #N/A

Sheet ITEM MASTER
A1: Item Id | B1: BOM Hdr Item Name | C1: Brand | D1: Item Id1 | E1: Item_Name | F1: Qty | G1: UOM_Name
A2: 34540 | B2: 108 LIFE DETOX 24/30 PYRAMID ENV TBGS | C2: 108 LIFE | D2: 34543 | E2: 108 LIFE DETOX 30 PYRAMID ENV TBGS | F2: 24 | G2: CTN | H2: BLEND DETOX HERBAL 108 PY TB
A3: 34541 | B3: 108 LIFE HIBISCUS LEMON GINGER 24/30 PYRAMID ENV TBGS | C3: 108 LIFE | D3: 34542 | E3: 108 LIFE HIBISCUS LEMON GINGER 30 PYRAMID ENV TBGS | F3: 24 | G3: CTN | H3: BLEND HERBAL LEMON GINGER CC EXOTIC
A4: 34539 | B4: 108 LIFE KASHMIRI KAHWA 24/30 PYRAMID ENV TBGS | C4: 108 LIFE | D4: 34544 | E4: 108 LIFE KASHMIRI KAHWA 30 PYRAMID ENV TBGS | F4: 24 | G4: CTN | H4: BLEND GREEN TEA KASHMIRI KAHWA CC EXOTIC
A5: 2738 | B5: AARAMBHA ASSAM BOGO 48/25 DC SF TAG TBGS | C5: AARAMBHA | D5: 2739 | E5: AARAMBHA ASSAM 25 DC SF TAG TBGS | F5: 48 | G5: CTN | H5: BLEND 909
A6: 19192 | B6: AARAMBHA ASSAM CTC TEA 36/100 DC SF HS TAG TBGS | C6: AARAMBHA | D6: 19191 | E6: AARAMBHA ASSAM CTC TEA 100 DC SF HS TAG TBGS | F6: 36 | G6: CTN | H6: BLEND 909
A7: 2751 | B7: AARAMBHA GREEN 24/25 DC SF HS ENV TBGS | C7: AARAMBHA | D7: 2752 | E7: AARAMBHA GREEN 25 DC SF HS ENV TBGS | F7: 24 | G7: CTN | H7: BLEND TEAME GREEN
A8: 18991 | B8: AARAMBHA HONEY LEMON GREEN 24/25 DC SF HS ENV TBGS | C8: AARAMBHA | D8: 2758 | E8: AARAMBHA HONEY LEMON GREEN 25 DC SF HS ENV TBGS | F8: 24 | G8: CTN | H8: BLEND GREEN TEA HONEY LEMON RELIANCE TBC
A9: 28708 | B9: AFRICA CHOICE 12/100 DC ENV TBGS | C9: AFRICA`S CHOICE | D9: 28717 | E9: AFRICA CHOICE 100 DC ENV TBGS | F9: 12 | G9: CTN | H9: BLEND 786
A10: 26730 | B10: AFRICA CHOICE 24/25 DC ENV TBGS | C10: AFRICA`S CHOICE | D10: 26752 | E10: AFRICA CHOICE 25 DC ENV TBGS | F10: 24 | G10: CTN | H10: BLEND 786
A11: 21745 | B11: AHOLD RFA 12/100 DCF PENV TBGS | C11: AHOLD | D11: 21757 | E11: AHOLD RFA 100 DCF PENV TBGS | F11: 12 | G11: CTN | H11: BLEND 7001RF
A12: 21758 | B12: AHOLD RFA 12/100 PENV TBGS | C12: AHOLD | D12: 21765 | E12: AHOLD RFA 100 PENV TBGS | F12: 12 | G12: CTN | H12: BLEND 7002RF
A13: 22180 | B13: AHOLD STOP SHOP 12/24 PFSTAG TBGS | C13: AHOLD | D13: 22801 | E13: AHOLD STOP SHOP 24 PFSTAG TBGS | F13: 12 | G13: CTN | H13: BLEND 7004RF
... A21: 20485 | B21: AL FINA 12/100 DC ENV TBGS | C21: AL FINA | D21: 20488 | E21: AL FINA 100 DC ENV TBGS WITHOUT SPOON | F21: 12 | G21: CTN | H21: BLEND A33
A22: 990 | B22: AL FINA 12/100 DC ENV TBGS WITH SPOON | C22: AL FINA | D22: 991 | E22: AL FINA 100 DC ENV TBGS | F22: 12 | G22: CTN | H22: =#N/A
A23: 996 | B23: AL FINA 12/100 DC ENV TBGS WITH SPOON AND TSHIRT | C23: AL FINA | D23: 991 | E23: AL FINA 100 DC ENV TBGS | F23: 12 | G23: CTN | H23: =#N/A
A24: 22432 | B24: AL FINA 12/100 DC ENV TBGS WITH SPOON AND TSHIRT NPBQ | C24: AL FINA | D24: 22430 | E24: AL FINA 100 DC ENV TBGS WITH SPOON (NPBQ) | F24: 12 | G24: CTN | H24: BLEND A33
A25: 22432 | B25: AL FINA 12/100 DC ENV TBGS WITH SPOON AND TSHIRT NPBQ | C25: AL FINA | D25: 22948 | E25: AL FINA 12/100 DC ENV TBGS WITH SPOON NPBQ | F25: 1 | G25: CFC | H25: =#N/A
A26: 22948 | B26: AL FINA 12/100 DC ENV TBGS WITH SPOON NPBQ | C26: AL FINA | D26: 22430 | E26: AL FINA 100 DC ENV TBGS WITH SPOON (NPBQ) | F26: 12 | G26: CTN | H26: BLEND A33
A27: 28506 | B27: AL FINA 12/100 DC ENV TBGS WITH T-SHIRT | C27: AL FINA | D27: 20488 | E27: AL FINA 100 DC ENV TBGS WITHOUT SPOON | F27: 12 | G27: CTN | H27: BLEND A33
A28: 1003 | B28: AL FINA 12/100 SC ENV TBGS WITH SPOON | C28: AL FINA | D28: 1004 | E28: AL FINA 100 SC ENV TBGS | F28: 12 | G28: CTN | H28: =#N/A
A29: 1010 | B29: AL FINA 12/106 SC TAG TBGS | C29: AL FINA | D29: 1011 | E29: AL FINA 106 SC TAG TBGS | F29: 12 | G29: CTN | H29: =#N/A
A30: 17796 | B30: AL FINA 12/107 DC ENV TBGS (SKV) | C30: AL FINA | D30: 17872 | E30: AL FINA 107 DC ENV TBGS (SKV) | F30: 12 | G30: CTN | H30: BLEND A33
A31: 1016 | B31: AL FINA 24/25 DC ENV TBGS | C31: AL FINA | D31: 1021 | E31: AL FINA 25 DC ENV TBGS | F31: 24 | G31: CTN | H31: BLEND A33
A32: 17798 | B32: AL FINA 24/25 DC ENV TBGS (SKV) | C32: AL FINA | D32: 17873 | E32: AL FINA 25 DC ENV TBGS (SKV) | F32: 24 | G32: CTN | H32: BLEND A33
A33: 1020 | B33: AL FINA 24/25 DC ENV TBGS WITH TSHIRT | C33: AL FINA | D33: 1021 | E33: AL FINA 25 DC ENV TBGS | F33: 24 | G33: CTN | H33: BLEND A33
A34: 1022 | B34: AL FINA 24/50 DC ENV TBGS | C34: AL FINA | D34: 1027 | E34: AL FINA 50 DC ENV TBGS | F34: 24 | G34: CTN | H34: BLEND A33
A35: 1026 | B35: AL FINA 24/50 DC ENV TBGS WITH TSHIRT | C35: AL FINA | D35: 1027 | E35: AL FINA 50 DC ENV TBGS | F35: 24 | G35: CTN | H35: BLEND A33
A36: 1028 | B36: AL FINA 48/25 DC ENV TBGS WITH TSHIRT | C36: AL FINA | D36: 1021 | E36: AL FINA 25 DC ENV TBGS | F36: 48 | G36: CTN | H36: BLEND A33
A37: 1031 | B37: AL FINA 6/130 DC ENV TBGS PLASIC BOX | C37: AL FINA | D37: 1032 | E37: AL FINA 130 DC ENV TBGS PLASIC BOX | F37: 6 | G37: CTN | H37: BLEND A33
A38: 1037 | B38: AL FINA 80/25 SC ENV TBGS WITH T-SHIRT | C38: AL FINA | D38: 1038 | E38: AL FINA 25 SC ENV TBGS | F38: 80 | G38: CTN | H38: =#N/A
A39: 1041 | B39: AL FINA 80/27 SC TAG TBGS WITH TSHIRT | C39: AL FINA | D39: 1042 | E39: AL FINA 27 SC TAG TBGS WITH TSHIRT | F39: 80 | G39: CTN | H39: =#N/A
A40: 1047 | B40: AL FINA BLACK TEA CRANBERRY APPLE 24/25 SC ENV TBGS TSHIRT | C40: AL FINA | D40: 1048 | E40: AL FINA BLACK TEA CRANBERRY APPLE 25 SC ENV TBGS TSHIRT | F40: 24 | G40: CTN | H40: =#N/A
A41: 1053 | B41: AL FINA BLOOD PRESSURE 24/25 SC ENV TBGS | C41: AL FINA | D41: 1054 | E41: AL FINA BLOOD PRESSURE 25 SC ENV TBGS | F41: 24 | G41: CTN | H41: =#N/A
A42: 1060 | B42: AL FINA BLOOD PRESSURE 24/25 SC ENV TBGS WITH TSHIRT | C42: AL FINA | D42: 1054 | E42: AL FINA BLOOD PRESSURE 25 SC ENV TBGS | F42: 24 | G42: CTN | H42: =#N/A
A43: 33775 | B43: AL FINA CAPPUCCINO 3 IN 1 (25 GMS) 12 STRIPS X 10 SACHETS | C43: AL FINA | D43: 33862 | E43: AL FINA CAPPUCCINO 3 IN 1 (25GMS) | F43: 120 | G43: POUCH | H43: BLEND INSTANT CAPPUCCINO AFRICA
A44: 33775 | B44: AL FINA CAPPUCCINO 3 IN 1 (25 GMS) 12 STRIPS X 10 SACHETS | C44: AL FINA | D44: 33863 | E44: AL FINA CAPPUCCINO CHOCO GRANULE (0.5 GMS) | F44: 120 | G44: POUCH | H44: BLEND INSTANT CAPPUCCINO COCO GRANULE AFRICA
A45: 33936 | B45: AL FINA CAPPUCCINO 3 IN 1 (25 GMS) 12 STRIPS X 10 SACHETS WITH HANGER | C45: AL FINA | D45: 33862 | E45: AL FINA CAPPUCCINO 3 IN 1 (25GMS) | F45: 120 | G45: POUCH | H45: BLEND INSTANT CAPPUCCINO AFRICA
A46: 26081 | B46: AL FINA CHAMOMILE 24/25 DC ENV TBGS | C46: AL FINA | D46: 26526 | E46: AL FINA CHAMOMILE 25 DC ENV TBGS | F46: 24 | G46: CTN | H46: BLEND CHAMOMILE
A47: 1062 | B47: AL FINA CHAMOMILE 24/25 SC ENV TBGS | C47: AL FINA | D47: 1063 | E47: AL FINA CHAMOMILE 25 SC ENV TBGS | F47: 24 | G47: CTN | H47: =#N/A
...

Sheet TBGS PER CTN
A1: Item Id | B1: Item_Name | C1: Count For Capacity
A2: 34831 | B2: TE-A-ME CHAI GINGER 100 DC STAPLE FREE TBGS-XS | C2: 100
A3: 34543 | B3: 108 LIFE DETOX 30 PYRAMID ENV TBGS | C3: 30
A4: 34542 | B4: 108 LIFE HIBISCUS LEMON GINGER 30 PYRAMID ENV TBGS | C4: 30
A5: 34544 | B5: 108 LIFE KASHMIRI KAHWA 30 PYRAMID ENV TBGS | C5: 30
A6: 2739 | B6: AARAMBHA ASSAM 25 DC SF TAG TBGS | C6: 25
A7: 19191 | B7: AARAMBHA ASSAM CTC TEA 100 DC SF HS TAG TBGS | C7: 100
A8: 2752 | B8: AARAMBHA GREEN 25 DC SF HS ENV TBGS | C8: 25
A9: 2758 | B9: AARAMBHA HONEY LEMON GREEN 25 DC SF HS ENV TBGS | C9: 25
A10: 26752 | B10: AFRICA CHOICE 25 DC ENV TBGS | C10: 25
A11: 28717 | B11: AFRICA CHOICE 100 DC ENV TBGS | C11: 100
A12: 21757 | B12: AHOLD RFA 100 DCF PENV TBGS | C12: 100
A13: 21765 | B13: AHOLD RFA 100 PENV TBGS | C13: 100
... A1577: 35086 | B1577: ZUHUUR FRUITY CRANBERRY HERBAL 25 DC ENV TBGS | C1577: 25
B1578: BARISSIMO BLACK TEA 100 DC TAG TBGS | C1578: 100
B1579: GINNY 25 DC ENV TBGS | C1579: 25
B1580: BARISSIMO PEPPERMINT HERBAL TEA 20 DC SF ENV TBGS | C1580: 20
B1581: GOLD BOND WATERMELON 25 DC ENV TBGS | C1581: 25
B1582: BARISSIMO GREEN TEA POMEGRANATE 20 DC SF ENV TBGS | C1582: 20
B1583: BARISSIMO GINGER TURMERIC HERBAL TEA 20 DC SF ENV TBGS | C1583: 20
B1584: BARISSIMO CHAMOMILE HERBAL TEA 20 DC SF ENV TBGS | C1584: 20
B1585: BARISSIMO GREEN TEA 20 DC SF ENV TBGS | C1585: 20
B1586: BARISSIMO LEMON GINSENG GREEN TEA 20 DC SF ENV TBGS | C1586: 20
B1587: BARISSIMO CHAI BLACK TEA 20 DC SF ENV TBGS | C1587: 20
B1588: BARISSIMO EARL GREY BLACK TEA 20 DC SF ENV TBGS | C1588: 20
B1589: BARISSIMO DECAF BLACK TEA 20 DC SF ENV TBGS | C1589: 20
B1590: GV HIBISCUS 25 DC ENV TBGS | C1590: 25

Sheet MC CAPACITY MASTER
A1: MC CAPACITY MASTER (Day Capacity derived from Weekly_capacity_in_tbgs.xlsx, incl. real shifts/day)
A2: Machine Line | B2: Weekly Capacity (lakh TBGS, from source file) | C2: Day Capacity (Weekly x 100000 / 6)
A3: BREW MAGIC | B3: 0.2352 | C3: =B3*100000/6
A4: C250 | B4: 43.2 | C4: =B4*100000/6
A5: C250 AF | B5: 28.8 | C5: =B5*100000/6
A6: C250-A | B6: 43.2 | C6: =B6*100000/6
A7: C250F3 ENV | B7: 14.4 | C7: =B7*100000/6
A8: C250F3 HS | B8: 7.2 | C8: =B8*100000/6
A9: CONSTANTA ENV | B9: 23.49 | C9: =B9*100000/6
A10: CONSTANTA ENV BT | B10: 40.35 | C10: =B10*100000/6
A11: CONSTANTA ENV BT 25 | B11: 32.28 | C11: =B11*100000/6
A12: CONSTANTA ENV F | B12: 39.15 | C12: =B12*100000/6
A13: CONSTANTA ENV G | B13: 23.49 | C13: =B13*100000/6
A14: CONSTANTA ENV H | B14: 45 | C14: =B14*100000/6
... A41: VIKING-MULTITRACK | B41: 1.7136 | C41: =B41*100000/6

Sheet MC MASTER
H1: SHIFT
A2: MACHINE LINE | B2: PACKER | C2: OPERATOR | D2: MACHINE NO | E2: No. of Machines | F2: No. of Shifts/day | G2: Target Tbgs/Min | H2: HR | I2: MIN | J2: SHIFT MIN | K2: TBGS/ SHIFT | L2: TBGS /WEEK | M2: Achievable Capacity | N2: TBGS PER CFC | O2: CFC/Week | P2: CFC/ CNTR | Q2: WEEKLY CAPACITY IN CNTR | R2: UNIT CAPACITY (CNTR per machine x shift) - Arul Sir file
A3: C250 AF | E3: 5 | F3: 2 | P3: 3340 | R3: 0.17649701
A4: CONSTANTA ENV (FLAVOUR & BLACK TEA) | E4: 23 | F4: 2 | P4: 6375 | R4: 0.097588235
A5: CONSTANTA ENV (HERBAL) | E5: 9 | F5: 2 | P5: 3340 | R5: 0.093822355
A6: MD20 ENV | E6: 4 | F6: 2 | P6: 3340 | R6: 0.13891617
A7: PERFECTA ENV | E7: 3 | F7: 2 | P7: 3340 | R7: 0.20826048
A8: CONSTANTA TAG | E8: 6 | F8: 1 | P8: 2688 | R8: 0.11514509
A9: C250 | E9: 3 | F9: 2 | P9: 7200 | R9: 0.2046875
A10: VARIETIES PACK | E10: 1 | F10: 2 | P10: 7200 | R10: 0.2046875
A11: MD20 4GM TAG | E11: 1 | F11: 1 | P11: 4032 | R11: 0.20174541
A12: PERFECTA K 45 TAG | E12: 1 | F12: 1 | P12: 5040 | R12: 0.23794643
A13: MD20 HS | E13: 2 | F13: 1 | P13: 6500 | R13: 0.23386769
A14: CONSTANTA FAMILY SIZE | E14: 2 | F14: 0 | P14: 5720 | R14: 0
... A27: Pearl Pack-FFS POUCH | E27: 0.5 | F27: 1 | P27: 1200 | R27: 1.03125

Sheet ITEM CFC PER CONTAINER
A1: PRODUCT NAME | B1: CFC/Container
A2: AFRICA CHOICE 12/100 DC ENV TBGS | B2: 3321
A3: AFRICA CHOICE 24/25 DC ENV TBGS | B3: 6375
A4: AKOUNA INSTANT COFFEE 9/150 SACHETS (15 STRIPS X 10 SACHETS X 1.5 GMS) WITH HANGER
A5: AKOUNA COFFEE 3 IN 1 (25 GMS) 12 STRIPS X 10 SACHETS WITH HANGER
A6: AL FINA 12/100 DC ENV TBGS WITH T-SHIRT | B6: 3250
A7: AL FINA CAPPUCCINO 3 IN 1 (25 GMS) 12 STRIPS X 10 SACHETS WITH HANGER
A8: AL FINA CHAMOMILE 24/25 DC ENV TBGS | B8: 6375
A9: AL FINA CLOVE 24/25 DC ENV TBGS | B9: 6375
A10: AL FINA COCKTAIL 24/25 DC ENV TBGS | B10: 6375
A11: AL FINA COFFEE 3 IN 1 (20 GMS) 12 STRIPS X 10 SACHETS WITH HANGER
A12: AL FINA GINGER 24/25 DC ENV TBGS | B12: 6375
A13: AL FINA GREEN TEA 24/25 DC ENV TBGS | B13: 6375
A14: AL FINA LEMON 24/25 DC ENV TBGS | B14: 6375
A15: AL FINA MANGO 24/25 DC ENV TBGS | B15: 6375
A16: AL FINA MINT 24/25 DC ENV TBGS | B16: 6375
A17: AL FINA MIX 24/25 DC ENV TBGS | B17: 6375
A18: AL FINA ORANGE 24/25 DC ENV TBGS | B18: 6375
A19: AL FINA PINEAPPLE 24/25 DC ENV TBGS | B19: 6375
A20: AL FINA STRAWBERRY 24/25 DC ENV TBGS | B20: 6375
A21: AL FINA TAMARIND 24/25 DC ENV TBGS | B21: 6375
A22: ALDI VRUCHTENTHEE 24/20 DC SF ENV TBGS
A23: BARISSIMO BLACK TEA 6/100 DC TAG TBGS | B23: 4620
A24: BARISSIMO BLACK TEA COLLECTIONS 12/20 DC SF ENV TBGS | B24: 8320
A25: BARISSIMO BLACK TEA COLLECTIONS 12/20 DC SF ENV TBGS | B25: 7200
A26: BARISSIMO GREEN TEA COLLECTIONS 12/20 DC SF ENV TBGS | B26: 8320
A27: BARISSIMO GREEN TEA COLLECTIONS 12/20 DC SF ENV TBGS | B27: 7200
A28: BARISSIMO HERBAL TEA COLLECTIONS 12/20 DC SF ENV TBGS | B28: 8320
A29: BARISSIMO HERBAL TEA COLLECTIONS 12/20 DC SF ENV TBGS | B29: 7200
A30: BLUE DIAMOND GINGER 24/25 DC ENV TBGS | B30: 6375
A31: BLUE DIAMOND LEMON 24/25 DC ENV TBGS | B31: 6375
A32: BLUE DIAMOND MINT 24/25 DC ENV TBGS | B32: 6375
A33: BLUE DIAMOND ORANGE 24/25 DC ENV TBGS | B33: 6375
A34: BLUE DIAMOND STRAWBERRY 24/25 DC ENV TBGS | B34: 6375
A35: BLUE DIAMOND TAMARIND 24/25 DC ENV TBGS | B35: 6375
A36: BREW360 32-3 OZ BLK RND ITBS COPACK
A37: CENTRA GOLD BLEND TEA 12/80 TAGLESS TBGS | B37: 3220
A38: CHAYA 12/100 DC ENV TBGS | B38: 3321
A39: CHAYA 12/100 DC ENV TBGS WITH TSHIRT | B39: 3250
A40: CHAYA 24/25 DC ENV TBGS WITH T-SHIRT | B40: 6120
...

Sheet ORDER VS WEEK DISTRIBUTION
A1: Order Vs Week Distribution | H1: Based on Pending Production | U1: Based on Order Qty | AH1: Routing Line | AI1: Capacity Group
A2: Zone | B2: Region | D2: Machine Line | E2: No. of Machines | F2: No. of Shifts | G2: Capacity(In containers) | H2: W #41 | I2: W #42 | J2: W #43 | K2: W #44 | L2: W #45 | M2: W #46 | N2: W #47 | O2: W #48 | P2: W #49 | Q2: W #50 | R2: W #51 | S2: W #52 | U2: =H2 | V2: =I2 | W2: =J2 | X2: =K2 | Y2: =L2 | Z2: =M2 | AA2: =N2 | AB2: =O2 | ... AF2: =S2 | AH2: CONSTANTA ENV | AI2: CONSTANTA ENV (FLAVOUR & BLACK TEA)
A3: Zone 1 | B3: AFRICA | C3: DC | D3: C250 AF | E3: 5 | F3: 2 | G3: =IFERROR(IF(OR($F3=0,VLOOKUP($D3,'MC MASTER'!$A:$R,18,0)=0),"-",ROUND(VLOOKUP($D3,'MC MASTER'!$A:$R,18,0)*$E3*$F3,3)),"-") | H3: =IFERROR(SUMIFS(WORKING!$Y:$Y,WORKING!$X:$X,$D3,WORKING!$W:$W,H$500),"") | I3: =IFERROR(SUMIFS(WORKING!$Y:$Y,WORKING!$X:$X,$D3,WORKING!$W:$W,I$500),"") | J3: =IFERROR(SUMIFS(WORKING!$Y:$Y,WORKING!$X:$X,$D3,WORKING!$W:$W,J$500),"") | K3: =IFERROR(SUMIFS(WORKING!$Y:$Y,WORKING!$X:$X,$D3,WORKING!$W:$W,K$500),"") | L3: =IFERROR(SUMIFS(WORKING!$Y:$Y,WORKING!$X:$X,$D3,WORKING!$W:$W,L$500),"") | M3: =IFERROR(SUMIFS(WORKING!$Y:$Y,WORKING!$X:$X,$D3,WORKING!$W:$W,M$500),"") | N3: =IFERROR(SUMIFS(WORKING!$Y:$Y,WORKING!$X:$X,$D3,WORKING!$W:$W,N$500),"") | O3: =IFERROR(SUMIFS(WORKING!$Y:$Y,WORKING!$X:$X,$D3,WORKING!$W:$W,O$500),"") | ... S3: =IFERROR(SUMIFS(WORKING!$Y:$Y,WORKING!$X:$X,$D3,WORKING!$W:$W,S$500),"") | U3: =IFERROR(SUMIFS(WORKING!$Z:$Z,WORKING!$X:$X,$D3,WORKING!$W:$W,H$500),"") | V3: =IFERROR(SUMIFS(WORKING!$Z:$Z,WORKING!$X:$X,$D3,WORKING!$W:$W,I$500),"") | W3: =IFERROR(SUMIFS(WORKING!$Z:$Z,WORKING!$X:$X,$D3,WORKING!$W:$W,J$500),"") | X3: =IFERROR(SUMIFS(WORKING!$Z:$Z,WORKING!$X:$X,$D3,WORKING!$W:$W,K$500),"") | Y3: =IFERROR(SUMIFS(WORKING!$Z:$Z,WORKING!$X:$X,$D3,WORKING!$W:$W,L$500),"") | Z3: =IFERROR(SUMIFS(WORKING!$Z:$Z,WORKING!$X:$X,$D3,WORKING!$W:$W,M$500),"") | AA3: =IFERROR(SUMIFS(WORKING!$Z:$Z,WORKING!$X:$X,$D3,WORKING!$W:$W,N$500),"") | AB3: =IFERROR(SUMIFS(WORKING!$Z:$Z,WORKING!$X:$X,$D3,WORKING!$W:$W,O$500),"") | ... AF3: =IFERROR(SUMIFS(WORKING!$Z:$Z,WORKING!$X:$X,$D3,WORKING!$W:$W,S$500),"") | AH3: CONSTANTA ENV BT | AI3: CONSTANTA ENV (FLAVOUR & BLACK TEA)
D4: CONSTANTA ENV (FLAVOUR & BLACK TEA) | E4: 23 | F4: 2 | G4: =IFERROR(IF(OR($F4=0,VLOOKUP($D4,'MC MASTER'!$A:$R,18,0)=0),"-",ROUND(VLOOKUP($D4,'MC MASTER'!$A:$R,18,0)*$E4*$F4,3)),"-") | H4: =IFERROR(SUMIFS(WORKING!$Y:$Y,WORKING!$X:$X,$D4,WORKING!$W:$W,H$500),"") | I4: =IFERROR(SUMIFS(WORKING!$Y:$Y,WORKING!$X:$X,$D4,WORKING!$W:$W,I$500),"") | J4: =IFERROR(SUMIFS(WORKING!$Y:$Y,WORKING!$X:$X,$D4,WORKING!$W:$W,J$500),"") | K4: =IFERROR(SUMIFS(WORKING!$Y:$Y,WORKING!$X:$X,$D4,WORKING!$W:$W,K$500),"") | L4: =IFERROR(SUMIFS(WORKING!$Y:$Y,WORKING!$X:$X,$D4,WORKING!$W:$W,L$500),"") | M4: =IFERROR(SUMIFS(WORKING!$Y:$Y,WORKING!$X:$X,$D4,WORKING!$W:$W,M$500),"") | N4: =IFERROR(SUMIFS(WORKING!$Y:$Y,WORKING!$X:$X,$D4,WORKING!$W:$W,N$500),"") | O4: =IFERROR(SUMIFS(WORKING!$Y:$Y,WORKING!$X:$X,$D4,WORKING!$W:$W,O$500),"") | ... S4: =IFERROR(SUMIFS(WORKING!$Y:$Y,WORKING!$X:$X,$D4,WORKING!$W:$W,S$500),"") | U4: =IFERROR(SUMIFS(WORKING!$Z:$Z,WORKING!$X:$X,$D4,WORKING!$W:$W,H$500),"") | V4: =IFERROR(SUMIFS(WORKING!$Z:$Z,WORKING!$X:$X,$D4,WORKING!$W:$W,I$500),"") | W4: =IFERROR(SUMIFS(WORKING!$Z:$Z,WORKING!$X:$X,$D4,WORKING!$W:$W,J$500),"") | X4: =IFERROR(SUMIFS(WORKING!$Z:$Z,WORKING!$X:$X,$D4,WORKING!$W:$W,K$500),"") | Y4: =IFERROR(SUMIFS(WORKING!$Z:$Z,WORKING!$X:$X,$D4,WORKING!$W:$W,L$500),"") | Z4: =IFERROR(SUMIFS(WORKING!$Z:$Z,WORKING!$X:$X,$D4,WORKING!$W:$W,M$500),"") | AA4: =IFERROR(SUMIFS(WORKING!$Z:$Z,WORKING!$X:$X,$D4,WORKING!$W:$W,N$500),"") | AB4: =IFERROR(SUMIFS(WORKING!$Z:$Z,WORKING!$X:$X,$D4,WORKING!$W:$W,O$500),"") | ... AF4: =IFERROR(SUMIFS(WORKING!$Z:$Z,WORKING!$X:$X,$D4,WORKING!$W:$W,S$500),"") | AH4: CONSTANTA ENV BT 25 | AI4: CONSTANTA ENV (FLAVOUR & BLACK TEA)
D5: CONSTANTA ENV (HERBAL) | E5: 9 | F5: 2 | G5: =IFERROR(IF(OR($F5=0,VLOOKUP($D5,'MC MASTER'!$A:$R,18,0)=0),"-",ROUND(VLOOKUP($D5,'MC MASTER'!$A:$R,18,0)*$E5*$F5,3)),"-") | H5: =IFERROR(SUMIFS(WORKING!$Y:$Y,WORKING!$X:$X,$D5,WORKING!$W:$W,H$500),"") | I5: =IFERROR(SUMIFS(WORKING!$Y:$Y,WORKING!$X:$X,$D5,WORKING!$W:$W,I$500),"") | J5: =IFERROR(SUMIFS(WORKING!$Y:$Y,WORKING!$X:$X,$D5,WORKING!$W:$W,J$500),"") | K5: =IFERROR(SUMIFS(WORKING!$Y:$Y,WORKING!$X:$X,$D5,WORKING!$W:$W,K$500),"") | L5: =IFERROR(SUMIFS(WORKING!$Y:$Y,WORKING!$X:$X,$D5,WORKING!$W:$W,L$500),"") | M5: =IFERROR(SUMIFS(WORKING!$Y:$Y,WORKING!$X:$X,$D5,WORKING!$W:$W,M$500),"") | N5: =IFERROR(SUMIFS(WORKING!$Y:$Y,WORKING!$X:$X,$D5,WORKING!$W:$W,N$500),"") | O5: =IFERROR(SUMIFS(WORKING!$Y:$Y,WORKING!$X:$X,$D5,WORKING!$W:$W,O$500),"") | ... S5: =IFERROR(SUMIFS(WORKING!$Y:$Y,WORKING!$X:$X,$D5,WORKING!$W:$W,S$500),"") | U5: =IFERROR(SUMIFS(WORKING!$Z:$Z,WORKING!$X:$X,$D5,WORKING!$W:$W,H$500),"") | V5: =IFERROR(SUMIFS(WORKING!$Z:$Z,WORKING!$X:$X,$D5,WORKING!$W:$W,I$500),"") | W5: =IFERROR(SUMIFS(WORKING!$Z:$Z,WORKING!$X:$X,$D5,WORKING!$W:$W,J$500),"") | X5: =IFERROR(SUMIFS(WORKING!$Z:$Z,WORKING!$X:$X,$D5,WORKING!$W:$W,K$500),"") | Y5: =IFERROR(SUMIFS(WORKING!$Z:$Z,WORKING!$X:$X,$D5,WORKING!$W:$W,L$500),"") | Z5: =IFERROR(SUMIFS(WORKING!$Z:$Z,WORKING!$X:$X,$D5,WORKING!$W:$W,M$500),"") | AA5: =IFERROR(SUMIFS(WORKING!$Z:$Z,WORKING!$X:$X,$D5,WORKING!$W:$W,N$500),"") | AB5: =IFERROR(SUMIFS(WORKING!$Z:$Z,WORKING!$X:$X,$D5,WORKING!$W:$W,O$500),"") | ... AF5: =IFERROR(SUMIFS(WORKING!$Z:$Z,WORKING!$X:$X,$D5,WORKING!$W:$W,S$500),"") | AH5: CONSTANTA ENV F | AI5: CONSTANTA ENV (FLAVOUR & BLACK TEA)
D6: MD20 ENV | E6: 4 | F6: 2 | G6: =IFERROR(IF(OR($F6=0,VLOOKUP($D6,'MC MASTER'!$A:$R,18,0)=0),"-",ROUND(VLOOKUP($D6,'MC MASTER'!$A:$R,18,0)*$E6*$F6,3)),"-") | H6: =IFERROR(SUMIFS(WORKING!$Y:$Y,WORKING!$X:$X,$D6,WORKING!$W:$W,H$500),"") | I6: =IFERROR(SUMIFS(WORKING!$Y:$Y,WORKING!$X:$X,$D6,WORKING!$W:$W,I$500),"") | J6: =IFERROR(SUMIFS(WORKING!$Y:$Y,WORKING!$X:$X,$D6,WORKING!$W:$W,J$500),"") | K6: =IFERROR(SUMIFS(WORKING!$Y:$Y,WORKING!$X:$X,$D6,WORKING!$W:$W,K$500),"") | L6: =IFERROR(SUMIFS(WORKING!$Y:$Y,WORKING!$X:$X,$D6,WORKING!$W:$W,L$500),"") | M6: =IFERROR(SUMIFS(WORKING!$Y:$Y,WORKING!$X:$X,$D6,WORKING!$W:$W,M$500),"") | N6: =IFERROR(SUMIFS(WORKING!$Y:$Y,WORKING!$X:$X,$D6,WORKING!$W:$W,N$500),"") | O6: =IFERROR(SUMIFS(WORKING!$Y:$Y,WORKING!$X:$X,$D6,WORKING!$W:$W,O$500),"") | ... S6: =IFERROR(SUMIFS(WORKING!$Y:$Y,WORKING!$X:$X,$D6,WORKING!$W:$W,S$500),"") | U6: =IFERROR(SUMIFS(WORKING!$Z:$Z,WORKING!$X:$X,$D6,WORKING!$W:$W,H$500),"") | V6: =IFERROR(SUMIFS(WORKING!$Z:$Z,WORKING!$X:$X,$D6,WORKING!$W:$W,I$500),"") | W6: =IFERROR(SUMIFS(WORKING!$Z:$Z,WORKING!$X:$X,$D6,WORKING!$W:$W,J$500),"") | X6: =IFERROR(SUMIFS(WORKING!$Z:$Z,WORKING!$X:$X,$D6,WORKING!$W:$W,K$500),"") | Y6: =IFERROR(SUMIFS(WORKING!$Z:$Z,WORKING!$X:$X,$D6,WORKING!$W:$W,L$500),"") | Z6: =IFERROR(SUMIFS(WORKING!$Z:$Z,WORKING!$X:$X,$D6,WORKING!$W:$W,M$500),"") | AA6: =IFERROR(SUMIFS(WORKING!$Z:$Z,WORKING!$X:$X,$D6,WORKING!$W:$W,N$500),"") | AB6: =IFERROR(SUMIFS(WORKING!$Z:$Z,WORKING!$X:$X,$D6,WORKING!$W:$W,O$500),"") | ... AF6: =IFERROR(SUMIFS(WORKING!$Z:$Z,WORKING!$X:$X,$D6,WORKING!$W:$W,S$500),"") | AH6: CONSTANTA ENV G | AI6: CONSTANTA ENV (FLAVOUR & BLACK TEA)
D7: PERFECTA ENV | E7: 3 | F7: 2 | G7: =IFERROR(IF(OR($F7=0,VLOOKUP($D7,'MC MASTER'!$A:$R,18,0)=0),"-",ROUND(VLOOKUP($D7,'MC MASTER'!$A:$R,18,0)*$E7*$F7,3)),"-") | H7: =IFERROR(SUMIFS(WORKING!$Y:$Y,WORKING!$X:$X,$D7,WORKING!$W:$W,H$500),"") | I7: =IFERROR(SUMIFS(WORKING!$Y:$Y,WORKING!$X:$X,$D7,WORKING!$W:$W,I$500),"") | J7: =IFERROR(SUMIFS(WORKING!$Y:$Y,WORKING!$X:$X,$D7,WORKING!$W:$W,J$500),"") | K7: =IFERROR(SUMIFS(WORKING!$Y:$Y,WORKING!$X:$X,$D7,WORKING!$W:$W,K$500),"") | L7: =IFERROR(SUMIFS(WORKING!$Y:$Y,WORKING!$X:$X,$D7,WORKING!$W:$W,L$500),"") | M7: =IFERROR(SUMIFS(WORKING!$Y:$Y,WORKING!$X:$X,$D7,WORKING!$W:$W,M$500),"") | N7: =IFERROR(SUMIFS(WORKING!$Y:$Y,WORKING!$X:$X,$D7,WORKING!$W:$W,N$500),"") | O7: =IFERROR(SUMIFS(WORKING!$Y:$Y,WORKING!$X:$X,$D7,WORKING!$W:$W,O$500),"") | ... S7: =IFERROR(SUMIFS(WORKING!$Y:$Y,WORKING!$X:$X,$D7,WORKING!$W:$W,S$500),"") | U7: =IFERROR(SUMIFS(WORKING!$Z:$Z,WORKING!$X:$X,$D7,WORKING!$W:$W,H$500),"") | V7: =IFERROR(SUMIFS(WORKING!$Z:$Z,WORKING!$X:$X,$D7,WORKING!$W:$W,I$500),"") | W7: =IFERROR(SUMIFS(WORKING!$Z:$Z,WORKING!$X:$X,$D7,WORKING!$W:$W,J$500),"") | X7: =IFERROR(SUMIFS(WORKING!$Z:$Z,WORKING!$X:$X,$D7,WORKING!$W:$W,K$500),"") | Y7: =IFERROR(SUMIFS(WORKING!$Z:$Z,WORKING!$X:$X,$D7,WORKING!$W:$W,L$500),"") | Z7: =IFERROR(SUMIFS(WORKING!$Z:$Z,WORKING!$X:$X,$D7,WORKING!$W:$W,M$500),"") | AA7: =IFERROR(SUMIFS(WORKING!$Z:$Z,WORKING!$X:$X,$D7,WORKING!$W:$W,N$500),"") | AB7: =IFERROR(SUMIFS(WORKING!$Z:$Z,WORKING!$X:$X,$D7,WORKING!$W:$W,O$500),"") | ... AF7: =IFERROR(SUMIFS(WORKING!$Z:$Z,WORKING!$X:$X,$D7,WORKING!$W:$W,S$500),"") | AH7: CONSTANTA ENV H | AI7: CONSTANTA ENV (FLAVOUR & BLACK TEA)
D8: TOTAL | G8: =SUM(G3:G7) | H8: =SUM(H3:H7) | I8: =SUM(I3:I7) | J8: =SUM(J3:J7) | K8: =SUM(K3:K7) | L8: =SUM(L3:L7) | M8: =SUM(M3:M7) | N8: =SUM(N3:N7) | ... S8: =SUM(S3:S7) | U8: =SUM(U3:U7) | V8: =SUM(V3:V7) | W8: =SUM(W3:W7) | X8: =SUM(X3:X7) | Y8: =SUM(Y3:Y7) | Z8: =SUM(Z3:Z7) | AA8: =SUM(AA3:AA7) | AB8: =SUM(AB3:AB7) | ... AF8: =SUM(AF3:AF7) | AH8: CONSTANTA ENV HF | AI8: CONSTANTA ENV (FLAVOUR & BLACK TEA)
D9: Excess Order | H9: =IFERROR(IF(ROUND(H8-$G8,3)>0,ROUND(H8-$G8,3),""),"") | I9: =IFERROR(IF(ROUND(I8-$G8,3)>0,ROUND(I8-$G8,3),""),"") | J9: =IFERROR(IF(ROUND(J8-$G8,3)>0,ROUND(J8-$G8,3),""),"") | K9: =IFERROR(IF(ROUND(K8-$G8,3)>0,ROUND(K8-$G8,3),""),"") | L9: =IFERROR(IF(ROUND(L8-$G8,3)>0,ROUND(L8-$G8,3),""),"") | M9: =IFERROR(IF(ROUND(M8-$G8,3)>0,ROUND(M8-$G8,3),""),"") | N9: =IFERROR(IF(ROUND(N8-$G8,3)>0,ROUND(N8-$G8,3),""),"") | O9: =IFERROR(IF(ROUND(O8-$G8,3)>0,ROUND(O8-$G8,3),""),"") | ... S9: =IFERROR(IF(ROUND(S8-$G8,3)>0,ROUND(S8-$G8,3),""),"") | U9: =IFERROR(IF(ROUND(U8-$G8,3)>0,ROUND(U8-$G8,3),""),"") | V9: =IFERROR(IF(ROUND(V8-$G8,3)>0,ROUND(V8-$G8,3),""),"") | W9: =IFERROR(IF(ROUND(W8-$G8,3)>0,ROUND(W8-$G8,3),""),"") | X9: =IFERROR(IF(ROUND(X8-$G8,3)>0,ROUND(X8-$G8,3),""),"") | Y9: =IFERROR(IF(ROUND(Y8-$G8,3)>0,ROUND(Y8-$G8,3),""),"") | Z9: =IFERROR(IF(ROUND(Z8-$G8,3)>0,ROUND(Z8-$G8,3),""),"") | AA9: =IFERROR(IF(ROUND(AA8-$G8,3)>0,ROUND(AA8-$G8,3),""),"") | AB9: =IFERROR(IF(ROUND(AB8-$G8,3)>0,ROUND(AB8-$G8,3),""),"") | ... AF9: =IFERROR(IF(ROUND(AF8-$G8,3)>0,ROUND(AF8-$G8,3),""),"") | AH9: CONSTANTA ENV M | AI9: CONSTANTA ENV (FLAVOUR & BLACK TEA)
D10: Short Order | H10: =IFERROR(IF(ROUND($G8-H8,3)>0,ROUND($G8-H8,3),""),"") | I10: =IFERROR(IF(ROUND($G8-I8,3)>0,ROUND($G8-I8,3),""),"") | J10: =IFERROR(IF(ROUND($G8-J8,3)>0,ROUND($G8-J8,3),""),"") | K10: =IFERROR(IF(ROUND($G8-K8,3)>0,ROUND($G8-K8,3),""),"") | L10: =IFERROR(IF(ROUND($G8-L8,3)>0,ROUND($G8-L8,3),""),"") | M10: =IFERROR(IF(ROUND($G8-M8,3)>0,ROUND($G8-M8,3),""),"") | N10: =IFERROR(IF(ROUND($G8-N8,3)>0,ROUND($G8-N8,3),""),"") | O10: =IFERROR(IF(ROUND($G8-O8,3)>0,ROUND($G8-O8,3),""),"") | ... S10: =IFERROR(IF(ROUND($G8-S8,3)>0,ROUND($G8-S8,3),""),"") | U10: =IFERROR(IF(ROUND($G8-U8,3)>0,ROUND($G8-U8,3),""),"") | V10: =IFERROR(IF(ROUND($G8-V8,3)>0,ROUND($G8-V8,3),""),"") | W10: =IFERROR(IF(ROUND($G8-W8,3)>0,ROUND($G8-W8,3),""),"") | X10: =IFERROR(IF(ROUND($G8-X8,3)>0,ROUND($G8-X8,3),""),"") | Y10: =IFERROR(IF(ROUND($G8-Y8,3)>0,ROUND($G8-Y8,3),""),"") | Z10: =IFERROR(IF(ROUND($G8-Z8,3)>0,ROUND($G8-Z8,3),""),"") | AA10: =IFERROR(IF(ROUND($G8-AA8,3)>0,ROUND($G8-AA8,3),""),"") | AB10: =IFERROR(IF(ROUND($G8-AB8,3)>0,ROUND($G8-AB8,3),""),"") | ... AF10: =IFERROR(IF(ROUND($G8-AF8,3)>0,ROUND($G8-AF8,3),""),"") | AH10: C250 | AI10: C250
B11: AUSTRALIA | C11: DC TAG | D11: CONSTANTA TAG | E11: 6 | F11: 1 | G11: =IFERROR(IF(OR($F11=0,VLOOKUP($D11,'MC MASTER'!$A:$R,18,0)=0),"-",ROUND(VLOOKUP($D11,'MC MASTER'!$A:$R,18,0)*$E11*$F11,3)),"-") | H11: =IFERROR(SUMIFS(WORKING!$Y:$Y,WORKING!$X:$X,$D11,WORKING!$W:$W,H$500),"") | I11: =IFERROR(SUMIFS(WORKING!$Y:$Y,WORKING!$X:$X,$D11,WORKING!$W:$W,I$500),"") | J11: =IFERROR(SUMIFS(WORKING!$Y:$Y,WORKING!$X:$X,$D11,WORKING!$W:$W,J$500),"") | K11: =IFERROR(SUMIFS(WORKING!$Y:$Y,WORKING!$X:$X,$D11,WORKING!$W:$W,K$500),"") | L11: =IFERROR(SUMIFS(WORKING!$Y:$Y,WORKING!$X:$X,$D11,WORKING!$W:$W,L$500),"") | M11: =IFERROR(SUMIFS(WORKING!$Y:$Y,WORKING!$X:$X,$D11,WORKING!$W:$W,M$500),"") | N11: =IFERROR(SUMIFS(WORKING!$Y:$Y,WORKING!$X:$X,$D11,WORKING!$W:$W,N$500),"") | O11: =IFERROR(SUMIFS(WORKING!$Y:$Y,WORKING!$X:$X,$D11,WORKING!$W:$W,O$500),"") | ... S11: =IFERROR(SUMIFS(WORKING!$Y:$Y,WORKING!$X:$X,$D11,WORKING!$W:$W,S$500),"") | U11: =IFERROR(SUMIFS(WORKING!$Z:$Z,WORKING!$X:$X,$D11,WORKING!$W:$W,H$500),"") | V11: =IFERROR(SUMIFS(WORKING!$Z:$Z,WORKING!$X:$X,$D11,WORKING!$W:$W,I$500),"") | W11: =IFERROR(SUMIFS(WORKING!$Z:$Z,WORKING!$X:$X,$D11,WORKING!$W:$W,J$500),"") | X11: =IFERROR(SUMIFS(WORKING!$Z:$Z,WORKING!$X:$X,$D11,WORKING!$W:$W,K$500),"") | Y11: =IFERROR(SUMIFS(WORKING!$Z:$Z,WORKING!$X:$X,$D11,WORKING!$W:$W,L$500),"") | Z11: =IFERROR(SUMIFS(WORKING!$Z:$Z,WORKING!$X:$X,$D11,WORKING!$W:$W,M$500),"") | AA11: =IFERROR(SUMIFS(WORKING!$Z:$Z,WORKING!$X:$X,$D11,WORKING!$W:$W,N$500),"") | AB11: =IFERROR(SUMIFS(WORKING!$Z:$Z,WORKING!$X:$X,$D11,WORKING!$W:$W,O$500),"") | ... AF11: =IFERROR(SUMIFS(WORKING!$Z:$Z,WORKING!$X:$X,$D11,WORKING!$W:$W,S$500),"") | AH11: C250 AF | AI11: C250 AF
D12: TOTAL | G12: =SUM(G11:G11) | H12: =SUM(H11:H11) | I12: =SUM(I11:I11) | J12: =SUM(J11:J11) | K12: =SUM(K11:K11) | L12: =SUM(L11:L11) | M12: =SUM(M11:M11) | N12: =SUM(N11:N11) | ... S12: =SUM(S11:S11) | U12: =SUM(U11:U11) | V12: =SUM(V11:V11) | W12: =SUM(W11:W11) | X12: =SUM(X11:X11) | Y12: =SUM(Y11:Y11) | Z12: =SUM(Z11:Z11) | AA12: =SUM(AA11:AA11) | AB12: =SUM(AB11:AB11) | ... AF12: =SUM(AF11:AF11) | AH12: C250-A | AI12: C250-A
D13: Excess Order | H13: =IFERROR(IF(ROUND(H12-$G12,3)>0,ROUND(H12-$G12,3),""),"") | I13: =IFERROR(IF(ROUND(I12-$G12,3)>0,ROUND(I12-$G12,3),""),"") | J13: =IFERROR(IF(ROUND(J12-$G12,3)>0,ROUND(J12-$G12,3),""),"") | K13: =IFERROR(IF(ROUND(K12-$G12,3)>0,ROUND(K12-$G12,3),""),"") | L13: =IFERROR(IF(ROUND(L12-$G12,3)>0,ROUND(L12-$G12,3),""),"") | M13: =IFERROR(IF(ROUND(M12-$G12,3)>0,ROUND(M12-$G12,3),""),"") | N13: =IFERROR(IF(ROUND(N12-$G12,3)>0,ROUND(N12-$G12,3),""),"") | O13: =IFERROR(IF(ROUND(O12-$G12,3)>0,ROUND(O12-$G12,3),""),"") | ... S13: =IFERROR(IF(ROUND(S12-$G12,3)>0,ROUND(S12-$G12,3),""),"") | U13: =IFERROR(IF(ROUND(U12-$G12,3)>0,ROUND(U12-$G12,3),""),"") | V13: =IFERROR(IF(ROUND(V12-$G12,3)>0,ROUND(V12-$G12,3),""),"") | W13: =IFERROR(IF(ROUND(W12-$G12,3)>0,ROUND(W12-$G12,3),""),"") | X13: =IFERROR(IF(ROUND(X12-$G12,3)>0,ROUND(X12-$G12,3),""),"") | Y13: =IFERROR(IF(ROUND(Y12-$G12,3)>0,ROUND(Y12-$G12,3),""),"") | Z13: =IFERROR(IF(ROUND(Z12-$G12,3)>0,ROUND(Z12-$G12,3),""),"") | AA13: =IFERROR(IF(ROUND(AA12-$G12,3)>0,ROUND(AA12-$G12,3),""),"") | AB13: =IFERROR(IF(ROUND(AB12-$G12,3)>0,ROUND(AB12-$G12,3),""),"") | ... AF13: =IFERROR(IF(ROUND(AF12-$G12,3)>0,ROUND(AF12-$G12,3),""),"") | AH13: C250F3 ENV | AI13: C250F3 ENV
D14: Short Order | H14: =IFERROR(IF(ROUND($G12-H12,3)>0,ROUND($G12-H12,3),""),"") | I14: =IFERROR(IF(ROUND($G12-I12,3)>0,ROUND($G12-I12,3),""),"") | J14: =IFERROR(IF(ROUND($G12-J12,3)>0,ROUND($G12-J12,3),""),"") | K14: =IFERROR(IF(ROUND($G12-K12,3)>0,ROUND($G12-K12,3),""),"") | L14: =IFERROR(IF(ROUND($G12-L12,3)>0,ROUND($G12-L12,3),""),"") | M14: =IFERROR(IF(ROUND($G12-M12,3)>0,ROUND($G12-M12,3),""),"") | N14: =IFERROR(IF(ROUND($G12-N12,3)>0,ROUND($G12-N12,3),""),"") | O14: =IFERROR(IF(ROUND($G12-O12,3)>0,ROUND($G12-O12,3),""),"") | ... S14: =IFERROR(IF(ROUND($G12-S12,3)>0,ROUND($G12-S12,3),""),"") | U14: =IFERROR(IF(ROUND($G12-U12,3)>0,ROUND($G12-U12,3),""),"") | V14: =IFERROR(IF(ROUND($G12-V12,3)>0,ROUND($G12-V12,3),""),"") | W14: =IFERROR(IF(ROUND($G12-W12,3)>0,ROUND($G12-W12,3),""),"") | X14: =IFERROR(IF(ROUND($G12-X12,3)>0,ROUND($G12-X12,3),""),"") | Y14: =IFERROR(IF(ROUND($G12-Y12,3)>0,ROUND($G12-Y12,3),""),"") | Z14: =IFERROR(IF(ROUND($G12-Z12,3)>0,ROUND($G12-Z12,3),""),"") | AA14: =IFERROR(IF(ROUND($G12-AA12,3)>0,ROUND($G12-AA12,3),""),"") | AB14: =IFERROR(IF(ROUND($G12-AB12,3)>0,ROUND($G12-AB12,3),""),"") | ... AF14: =IFERROR(IF(ROUND($G12-AF12,3)>0,ROUND($G12-AF12,3),""),"") | AH14: C250F3 HS | AI14: C250F3 HS
B15: EUROPE | C15: DC SF CRIMP | D15: C250 | E15: 3 | F15: 2 | G15: =IFERROR(IF(OR($F15=0,VLOOKUP($D15,'MC MASTER'!$A:$R,18,0)=0),"-",ROUND(VLOOKUP($D15,'MC MASTER'!$A:$R,18,0)*$E15*$F15,3)),"-") | H15: =IFERROR(SUMIFS(WORKING!$Y:$Y,WORKING!$X:$X,$D15,WORKING!$W:$W,H$500),"") | I15: =IFERROR(SUMIFS(WORKING!$Y:$Y,WORKING!$X:$X,$D15,WORKING!$W:$W,I$500),"") | J15: =IFERROR(SUMIFS(WORKING!$Y:$Y,WORKING!$X:$X,$D15,WORKING!$W:$W,J$500),"") | K15: =IFERROR(SUMIFS(WORKING!$Y:$Y,WORKING!$X:$X,$D15,WORKING!$W:$W,K$500),"") | L15: =IFERROR(SUMIFS(WORKING!$Y:$Y,WORKING!$X:$X,$D15,WORKING!$W:$W,L$500),"") | M15: =IFERROR(SUMIFS(WORKING!$Y:$Y,WORKING!$X:$X,$D15,WORKING!$W:$W,M$500),"") | N15: =IFERROR(SUMIFS(WORKING!$Y:$Y,WORKING!$X:$X,$D15,WORKING!$W:$W,N$500),"") | O15: =IFERROR(SUMIFS(WORKING!$Y:$Y,WORKING!$X:$X,$D15,WORKING!$W:$W,O$500),"") | ... S15: =IFERROR(SUMIFS(WORKING!$Y:$Y,WORKING!$X:$X,$D15,WORKING!$W:$W,S$500),"") | U15: =IFERROR(SUMIFS(WORKING!$Z:$Z,WORKING!$X:$X,$D15,WORKING!$W:$W,H$500),"") | V15: =IFERROR(SUMIFS(WORKING!$Z:$Z,WORKING!$X:$X,$D15,WORKING!$W:$W,I$500),"") | W15: =IFERROR(SUMIFS(WORKING!$Z:$Z,WORKING!$X:$X,$D15,WORKING!$W:$W,J$500),"") | X15: =IFERROR(SUMIFS(WORKING!$Z:$Z,WORKING!$X:$X,$D15,WORKING!$W:$W,K$500),"") | Y15: =IFERROR(SUMIFS(WORKING!$Z:$Z,WORKING!$X:$X,$D15,WORKING!$W:$W,L$500),"") | Z15: =IFERROR(SUMIFS(WORKING!$Z:$Z,WORKING!$X:$X,$D15,WORKING!$W:$W,M$500),"") | AA15: =IFERROR(SUMIFS(WORKING!$Z:$Z,WORKING!$X:$X,$D15,WORKING!$W:$W,N$500),"") | AB15: =IFERROR(SUMIFS(WORKING!$Z:$Z,WORKING!$X:$X,$D15,WORKING!$W:$W,O$500),"") | ... AF15: =IFERROR(SUMIFS(WORKING!$Z:$Z,WORKING!$X:$X,$D15,WORKING!$W:$W,S$500),"") | AH15: MD20 4GM TAG | AI15: MD20 4GM TAG
D16: VARIETIES PACK | E16: 1 | F16: 2 | G16: =IFERROR(IF(OR($F16=0,VLOOKUP($D16,'MC MASTER'!$A:$R,18,0)=0),"-",ROUND(VLOOKUP($D16,'MC MASTER'!$A:$R,18,0)*$E16*$F16,3)),"-") | H16: =IFERROR(SUMIFS(WORKING!$Y:$Y,WORKING!$X:$X,$D16,WORKING!$W:$W,H$500),"") | I16: =IFERROR(SUMIFS(WORKING!$Y:$Y,WORKING!$X:$X,$D16,WORKING!$W:$W,I$500),"") | J16: =IFERROR(SUMIFS(WORKING!$Y:$Y,WORKING!$X:$X,$D16,WORKING!$W:$W,J$500),"") | K16: =IFERROR(SUMIFS(WORKING!$Y:$Y,WORKING!$X:$X,$D16,WORKING!$W:$W,K$500),"") | L16: =IFERROR(SUMIFS(WORKING!$Y:$Y,WORKING!$X:$X,$D16,WORKING!$W:$W,L$500),"") | M16: =IFERROR(SUMIFS(WORKING!$Y:$Y,WORKING!$X:$X,$D16,WORKING!$W:$W,M$500),"") | N16: =IFERROR(SUMIFS(WORKING!$Y:$Y,WORKING!$X:$X,$D16,WORKING!$W:$W,N$500),"") | O16: =IFERROR(SUMIFS(WORKING!$Y:$Y,WORKING!$X:$X,$D16,WORKING!$W:$W,O$500),"") | ... S16: =IFERROR(SUMIFS(WORKING!$Y:$Y,WORKING!$X:$X,$D16,WORKING!$W:$W,S$500),"") | U16: =IFERROR(SUMIFS(WORKING!$Z:$Z,WORKING!$X:$X,$D16,WORKING!$W:$W,H$500),"") | V16: =IFERROR(SUMIFS(WORKING!$Z:$Z,WORKING!$X:$X,$D16,WORKING!$W:$W,I$500),"") | W16: =IFERROR(SUMIFS(WORKING!$Z:$Z,WORKING!$X:$X,$D16,WORKING!$W:$W,J$500),"") | X16: =IFERROR(SUMIFS(WORKING!$Z:$Z,WORKING!$X:$X,$D16,WORKING!$W:$W,K$500),"") | Y16: =IFERROR(SUMIFS(WORKING!$Z:$Z,WORKING!$X:$X,$D16,WORKING!$W:$W,L$500),"") | Z16: =IFERROR(SUMIFS(WORKING!$Z:$Z,WORKING!$X:$X,$D16,WORKING!$W:$W,M$500),"") | AA16: =IFERROR(SUMIFS(WORKING!$Z:$Z,WORKING!$X:$X,$D16,WORKING!$W:$W,N$500),"") | AB16: =IFERROR(SUMIFS(WORKING!$Z:$Z,WORKING!$X:$X,$D16,WORKING!$W:$W,O$500),"") | ... AF16: =IFERROR(SUMIFS(WORKING!$Z:$Z,WORKING!$X:$X,$D16,WORKING!$W:$W,S$500),"") | AH16: MD20 ENV | AI16: MD20 ENV
D17: TOTAL | G17: =SUM(G15:G16) | H17: =SUM(H15:H16) | I17: =SUM(I15:I16) | J17: =SUM(J15:J16) | K17: =SUM(K15:K16) | L17: =SUM(L15:L16) | M17: =SUM(M15:M16) | N17: =SUM(N15:N16) | ... S17: =SUM(S15:S16) | U17: =SUM(U15:U16) | V17: =SUM(V15:V16) | W17: =SUM(W15:W16) | X17: =SUM(X15:X16) | Y17: =SUM(Y15:Y16) | Z17: =SUM(Z15:Z16) | AA17: =SUM(AA15:AA16) | AB17: =SUM(AB15:AB16) | ... AF17: =SUM(AF15:AF16) | AH17: MD20 HS | AI17: MD20 HS
D18: Excess Order | H18: =IFERROR(IF(ROUND(H17-$G17,3)>0,ROUND(H17-$G17,3),""),"") | I18: =IFERROR(IF(ROUND(I17-$G17,3)>0,ROUND(I17-$G17,3),""),"") | J18: =IFERROR(IF(ROUND(J17-$G17,3)>0,ROUND(J17-$G17,3),""),"") | K18: =IFERROR(IF(ROUND(K17-$G17,3)>0,ROUND(K17-$G17,3),""),"") | L18: =IFERROR(IF(ROUND(L17-$G17,3)>0,ROUND(L17-$G17,3),""),"") | M18: =IFERROR(IF(ROUND(M17-$G17,3)>0,ROUND(M17-$G17,3),""),"") | N18: =IFERROR(IF(ROUND(N17-$G17,3)>0,ROUND(N17-$G17,3),""),"") | O18: =IFERROR(IF(ROUND(O17-$G17,3)>0,ROUND(O17-$G17,3),""),"") | ... S18: =IFERROR(IF(ROUND(S17-$G17,3)>0,ROUND(S17-$G17,3),""),"") | U18: =IFERROR(IF(ROUND(U17-$G17,3)>0,ROUND(U17-$G17,3),""),"") | V18: =IFERROR(IF(ROUND(V17-$G17,3)>0,ROUND(V17-$G17,3),""),"") | W18: =IFERROR(IF(ROUND(W17-$G17,3)>0,ROUND(W17-$G17,3),""),"") | X18: =IFERROR(IF(ROUND(X17-$G17,3)>0,ROUND(X17-$G17,3),""),"") | Y18: =IFERROR(IF(ROUND(Y17-$G17,3)>0,ROUND(Y17-$G17,3),""),"") | Z18: =IFERROR(IF(ROUND(Z17-$G17,3)>0,ROUND(Z17-$G17,3),""),"") | AA18: =IFERROR(IF(ROUND(AA17-$G17,3)>0,ROUND(AA17-$G17,3),""),"") | AB18: =IFERROR(IF(ROUND(AB17-$G17,3)>0,ROUND(AB17-$G17,3),""),"") | ... AF18: =IFERROR(IF(ROUND(AF17-$G17,3)>0,ROUND(AF17-$G17,3),""),"") | AH18: MAISA ENV | AI18: MAISA ENV
D19: Short Order | H19: =IFERROR(IF(ROUND($G17-H17,3)>0,ROUND($G17-H17,3),""),"") | I19: =IFERROR(IF(ROUND($G17-I17,3)>0,ROUND($G17-I17,3),""),"") | J19: =IFERROR(IF(ROUND($G17-J17,3)>0,ROUND($G17-J17,3),""),"") | K19: =IFERROR(IF(ROUND($G17-K17,3)>0,ROUND($G17-K17,3),""),"") | L19: =IFERROR(IF(ROUND($G17-L17,3)>0,ROUND($G17-L17,3),""),"") | M19: =IFERROR(IF(ROUND($G17-M17,3)>0,ROUND($G17-M17,3),""),"") | N19: =IFERROR(IF(ROUND($G17-N17,3)>0,ROUND($G17-N17,3),""),"") | O19: =IFERROR(IF(ROUND($G17-O17,3)>0,ROUND($G17-O17,3),""),"") | ... S19: =IFERROR(IF(ROUND($G17-S17,3)>0,ROUND($G17-S17,3),""),"") | U19: =IFERROR(IF(ROUND($G17-U17,3)>0,ROUND($G17-U17,3),""),"") | V19: =IFERROR(IF(ROUND($G17-V17,3)>0,ROUND($G17-V17,3),""),"") | W19: =IFERROR(IF(ROUND($G17-W17,3)>0,ROUND($G17-W17,3),""),"") | X19: =IFERROR(IF(ROUND($G17-X17,3)>0,ROUND($G17-X17,3),""),"") | Y19: =IFERROR(IF(ROUND($G17-Y17,3)>0,ROUND($G17-Y17,3),""),"") | Z19: =IFERROR(IF(ROUND($G17-Z17,3)>0,ROUND($G17-Z17,3),""),"") | AA19: =IFERROR(IF(ROUND($G17-AA17,3)>0,ROUND($G17-AA17,3),""),"") | AB19: =IFERROR(IF(ROUND($G17-AB17,3)>0,ROUND($G17-AB17,3),""),"") | ... AF19: =IFERROR(IF(ROUND($G17-AF17,3)>0,ROUND($G17-AF17,3),""),"") | AH19: MD20 ENV GARANT | AI19: MD20 ENV GARANT
C20: DC TAG | D20: MD20 4GM TAG | E20: 1 | F20: 1 | G20: =IFERROR(IF(OR($F20=0,VLOOKUP($D20,'MC MASTER'!$A:$R,18,0)=0),"-",ROUND(VLOOKUP($D20,'MC MASTER'!$A:$R,18,0)*$E20*$F20,3)),"-") | H20: =IFERROR(SUMIFS(WORKING!$Y:$Y,WORKING!$X:$X,$D20,WORKING!$W:$W,H$500),"") | I20: =IFERROR(SUMIFS(WORKING!$Y:$Y,WORKING!$X:$X,$D20,WORKING!$W:$W,I$500),"") | J20: =IFERROR(SUMIFS(WORKING!$Y:$Y,WORKING!$X:$X,$D20,WORKING!$W:$W,J$500),"") | K20: =IFERROR(SUMIFS(WORKING!$Y:$Y,WORKING!$X:$X,$D20,WORKING!$W:$W,K$500),"") | L20: =IFERROR(SUMIFS(WORKING!$Y:$Y,WORKING!$X:$X,$D20,WORKING!$W:$W,L$500),"") | M20: =IFERROR(SUMIFS(WORKING!$Y:$Y,WORKING!$X:$X,$D20,WORKING!$W:$W,M$500),"") | N20: =IFERROR(SUMIFS(WORKING!$Y:$Y,WORKING!$X:$X,$D20,WORKING!$W:$W,N$500),"") | O20: =IFERROR(SUMIFS(WORKING!$Y:$Y,WORKING!$X:$X,$D20,WORKING!$W:$W,O$500),"") | ... S20: =IFERROR(SUMIFS(WORKING!$Y:$Y,WORKING!$X:$X,$D20,WORKING!$W:$W,S$500),"") | U20: =IFERROR(SUMIFS(WORKING!$Z:$Z,WORKING!$X:$X,$D20,WORKING!$W:$W,H$500),"") | V20: =IFERROR(SUMIFS(WORKING!$Z:$Z,WORKING!$X:$X,$D20,WORKING!$W:$W,I$500),"") | W20: =IFERROR(SUMIFS(WORKING!$Z:$Z,WORKING!$X:$X,$D20,WORKING!$W:$W,J$500),"") | X20: =IFERROR(SUMIFS(WORKING!$Z:$Z,WORKING!$X:$X,$D20,WORKING!$W:$W,K$500),"") | Y20: =IFERROR(SUMIFS(WORKING!$Z:$Z,WORKING!$X:$X,$D20,WORKING!$W:$W,L$500),"") | Z20: =IFERROR(SUMIFS(WORKING!$Z:$Z,WORKING!$X:$X,$D20,WORKING!$W:$W,M$500),"") | AA20: =IFERROR(SUMIFS(WORKING!$Z:$Z,WORKING!$X:$X,$D20,WORKING!$W:$W,N$500),"") | AB20: =IFERROR(SUMIFS(WORKING!$Z:$Z,WORKING!$X:$X,$D20,WORKING!$W:$W,O$500),"") | ... AF20: =IFERROR(SUMIFS(WORKING!$Z:$Z,WORKING!$X:$X,$D20,WORKING!$W:$W,S$500),"") | AH20: MAISA TAGLESS | AI20: MAISA TAGLESS
D21: PERFECTA K 45 TAG | E21: 1 | F21: 1 | G21: =IFERROR(IF(OR($F21=0,VLOOKUP($D21,'MC MASTER'!$A:$R,18,0)=0),"-",ROUND(VLOOKUP($D21,'MC MASTER'!$A:$R,18,0)*$E21*$F21,3)),"-") | H21: =IFERROR(SUMIFS(WORKING!$Y:$Y,WORKING!$X:$X,$D21,WORKING!$W:$W,H$500),"") | I21: =IFERROR(SUMIFS(WORKING!$Y:$Y,WORKING!$X:$X,$D21,WORKING!$W:$W,I$500),"") | J21: =IFERROR(SUMIFS(WORKING!$Y:$Y,WORKING!$X:$X,$D21,WORKING!$W:$W,J$500),"") | K21: =IFERROR(SUMIFS(WORKING!$Y:$Y,WORKING!$X:$X,$D21,WORKING!$W:$W,K$500),"") | L21: =IFERROR(SUMIFS(WORKING!$Y:$Y,WORKING!$X:$X,$D21,WORKING!$W:$W,L$500),"") | M21: =IFERROR(SUMIFS(WORKING!$Y:$Y,WORKING!$X:$X,$D21,WORKING!$W:$W,M$500),"") | N21: =IFERROR(SUMIFS(WORKING!$Y:$Y,WORKING!$X:$X,$D21,WORKING!$W:$W,N$500),"") | O21: =IFERROR(SUMIFS(WORKING!$Y:$Y,WORKING!$X:$X,$D21,WORKING!$W:$W,O$500),"") | ... S21: =IFERROR(SUMIFS(WORKING!$Y:$Y,WORKING!$X:$X,$D21,WORKING!$W:$W,S$500),"") | U21: =IFERROR(SUMIFS(WORKING!$Z:$Z,WORKING!$X:$X,$D21,WORKING!$W:$W,H$500),"") | V21: =IFERROR(SUMIFS(WORKING!$Z:$Z,WORKING!$X:$X,$D21,WORKING!$W:$W,I$500),"") | W21: =IFERROR(SUMIFS(WORKING!$Z:$Z,WORKING!$X:$X,$D21,WORKING!$W:$W,J$500),"") | X21: =IFERROR(SUMIFS(WORKING!$Z:$Z,WORKING!$X:$X,$D21,WORKING!$W:$W,K$500),"") | Y21: =IFERROR(SUMIFS(WORKING!$Z:$Z,WORKING!$X:$X,$D21,WORKING!$W:$W,L$500),"") | Z21: =IFERROR(SUMIFS(WORKING!$Z:$Z,WORKING!$X:$X,$D21,WORKING!$W:$W,M$500),"") | AA21: =IFERROR(SUMIFS(WORKING!$Z:$Z,WORKING!$X:$X,$D21,WORKING!$W:$W,N$500),"") | AB21: =IFERROR(SUMIFS(WORKING!$Z:$Z,WORKING!$X:$X,$D21,WORKING!$W:$W,O$500),"") | ... AF21: =IFERROR(SUMIFS(WORKING!$Z:$Z,WORKING!$X:$X,$D21,WORKING!$W:$W,S$500),"") | AH21: CONSTANTA TAG | AI21: CONSTANTA TAG
D22: TOTAL | G22: =SUM(G20:G21) | H22: =SUM(H20:H21) | I22: =SUM(I20:I21) | J22: =SUM(J20:J21) | K22: =SUM(K20:K21) | L22: =SUM(L20:L21) | M22: =SUM(M20:M21) | N22: =SUM(N20:N21) | ... S22: =SUM(S20:S21) | U22: =SUM(U20:U21) | V22: =SUM(V20:V21) | W22: =SUM(W20:W21) | X22: =SUM(X20:X21) | Y22: =SUM(Y20:Y21) | Z22: =SUM(Z20:Z21) | AA22: =SUM(AA20:AA21) | AB22: =SUM(AB20:AB21) | ... AF22: =SUM(AF20:AF21) | AH22: CONSTANTA TAG (D) | AI22: CONSTANTA TAG
D23: Excess Order | H23: =IFERROR(IF(ROUND(H22-$G22,3)>0,ROUND(H22-$G22,3),""),"") | I23: =IFERROR(IF(ROUND(I22-$G22,3)>0,ROUND(I22-$G22,3),""),"") | J23: =IFERROR(IF(ROUND(J22-$G22,3)>0,ROUND(J22-$G22,3),""),"") | K23: =IFERROR(IF(ROUND(K22-$G22,3)>0,ROUND(K22-$G22,3),""),"") | L23: =IFERROR(IF(ROUND(L22-$G22,3)>0,ROUND(L22-$G22,3),""),"") | M23: =IFERROR(IF(ROUND(M22-$G22,3)>0,ROUND(M22-$G22,3),""),"") | N23: =IFERROR(IF(ROUND(N22-$G22,3)>0,ROUND(N22-$G22,3),""),"") | O23: =IFERROR(IF(ROUND(O22-$G22,3)>0,ROUND(O22-$G22,3),""),"") | ... S23: =IFERROR(IF(ROUND(S22-$G22,3)>0,ROUND(S22-$G22,3),""),"") | U23: =IFERROR(IF(ROUND(U22-$G22,3)>0,ROUND(U22-$G22,3),""),"") | V23: =IFERROR(IF(ROUND(V22-$G22,3)>0,ROUND(V22-$G22,3),""),"") | W23: =IFERROR(IF(ROUND(W22-$G22,3)>0,ROUND(W22-$G22,3),""),"") | X23: =IFERROR(IF(ROUND(X22-$G22,3)>0,ROUND(X22-$G22,3),""),"") | Y23: =IFERROR(IF(ROUND(Y22-$G22,3)>0,ROUND(Y22-$G22,3),""),"") | Z23: =IFERROR(IF(ROUND(Z22-$G22,3)>0,ROUND(Z22-$G22,3),""),"") | AA23: =IFERROR(IF(ROUND(AA22-$G22,3)>0,ROUND(AA22-$G22,3),""),"") | AB23: =IFERROR(IF(ROUND(AB22-$G22,3)>0,ROUND(AB22-$G22,3),""),"") | ... AF23: =IFERROR(IF(ROUND(AF22-$G22,3)>0,ROUND(AF22-$G22,3),""),"") | AH23: PERFACTA TAG | AI23: PERFACTA TAG
D24: Short Order | H24: =IFERROR(IF(ROUND($G22-H22,3)>0,ROUND($G22-H22,3),""),"") | I24: =IFERROR(IF(ROUND($G22-I22,3)>0,ROUND($G22-I22,3),""),"") | J24: =IFERROR(IF(ROUND($G22-J22,3)>0,ROUND($G22-J22,3),""),"") | K24: =IFERROR(IF(ROUND($G22-K22,3)>0,ROUND($G22-K22,3),""),"") | L24: =IFERROR(IF(ROUND($G22-L22,3)>0,ROUND($G22-L22,3),""),"") | M24: =IFERROR(IF(ROUND($G22-M22,3)>0,ROUND($G22-M22,3),""),"") | N24: =IFERROR(IF(ROUND($G22-N22,3)>0,ROUND($G22-N22,3),""),"") | O24: =IFERROR(IF(ROUND($G22-O22,3)>0,ROUND($G22-O22,3),""),"") | ... S24: =IFERROR(IF(ROUND($G22-S22,3)>0,ROUND($G22-S22,3),""),"") | U24: =IFERROR(IF(ROUND($G22-U22,3)>0,ROUND($G22-U22,3),""),"") | V24: =IFERROR(IF(ROUND($G22-V22,3)>0,ROUND($G22-V22,3),""),"") | W24: =IFERROR(IF(ROUND($G22-W22,3)>0,ROUND($G22-W22,3),""),"") | X24: =IFERROR(IF(ROUND($G22-X22,3)>0,ROUND($G22-X22,3),""),"") | Y24: =IFERROR(IF(ROUND($G22-Y22,3)>0,ROUND($G22-Y22,3),""),"") | Z24: =IFERROR(IF(ROUND($G22-Z22,3)>0,ROUND($G22-Z22,3),""),"") | AA24: =IFERROR(IF(ROUND($G22-AA22,3)>0,ROUND($G22-AA22,3),""),"") | AB24: =IFERROR(IF(ROUND($G22-AB22,3)>0,ROUND($G22-AB22,3),""),"") | ... AF24: =IFERROR(IF(ROUND($G22-AF22,3)>0,ROUND($G22-AF22,3),""),"") | AH24: PERFECTA K 45 TAG | AI24: PERFECTA K 45 TAG
B25: RUSSIA | C25: DC TAG | D25: MD20 HS | E25: 2 | F25: 1 | G25: =IFERROR(IF(OR($F25=0,VLOOKUP($D25,'MC MASTER'!$A:$R,18,0)=0),"-",ROUND(VLOOKUP($D25,'MC MASTER'!$A:$R,18,0)*$E25*$F25,3)),"-") | H25: =IFERROR(SUMIFS(WORKING!$Y:$Y,WORKING!$X:$X,$D25,WORKING!$W:$W,H$500),"") | I25: =IFERROR(SUMIFS(WORKING!$Y:$Y,WORKING!$X:$X,$D25,WORKING!$W:$W,I$500),"") | J25: =IFERROR(SUMIFS(WORKING!$Y:$Y,WORKING!$X:$X,$D25,WORKING!$W:$W,J$500),"") | K25: =IFERROR(SUMIFS(WORKING!$Y:$Y,WORKING!$X:$X,$D25,WORKING!$W:$W,K$500),"") | L25: =IFERROR(SUMIFS(WORKING!$Y:$Y,WORKING!$X:$X,$D25,WORKING!$W:$W,L$500),"") | M25: =IFERROR(SUMIFS(WORKING!$Y:$Y,WORKING!$X:$X,$D25,WORKING!$W:$W,M$500),"") | N25: =IFERROR(SUMIFS(WORKING!$Y:$Y,WORKING!$X:$X,$D25,WORKING!$W:$W,N$500),"") | O25: =IFERROR(SUMIFS(WORKING!$Y:$Y,WORKING!$X:$X,$D25,WORKING!$W:$W,O$500),"") | ... S25: =IFERROR(SUMIFS(WORKING!$Y:$Y,WORKING!$X:$X,$D25,WORKING!$W:$W,S$500),"") | U25: =IFERROR(SUMIFS(WORKING!$Z:$Z,WORKING!$X:$X,$D25,WORKING!$W:$W,H$500),"") | V25: =IFERROR(SUMIFS(WORKING!$Z:$Z,WORKING!$X:$X,$D25,WORKING!$W:$W,I$500),"") | W25: =IFERROR(SUMIFS(WORKING!$Z:$Z,WORKING!$X:$X,$D25,WORKING!$W:$W,J$500),"") | X25: =IFERROR(SUMIFS(WORKING!$Z:$Z,WORKING!$X:$X,$D25,WORKING!$W:$W,K$500),"") | Y25: =IFERROR(SUMIFS(WORKING!$Z:$Z,WORKING!$X:$X,$D25,WORKING!$W:$W,L$500),"") | Z25: =IFERROR(SUMIFS(WORKING!$Z:$Z,WORKING!$X:$X,$D25,WORKING!$W:$W,M$500),"") | AA25: =IFERROR(SUMIFS(WORKING!$Z:$Z,WORKING!$X:$X,$D25,WORKING!$W:$W,N$500),"") | AB25: =IFERROR(SUMIFS(WORKING!$Z:$Z,WORKING!$X:$X,$D25,WORKING!$W:$W,O$500),"") | ... AF25: =IFERROR(SUMIFS(WORKING!$Z:$Z,WORKING!$X:$X,$D25,WORKING!$W:$W,S$500),"") | AH25: CONSTANTA FAMILY SIZE | AI25: CONSTANTA FAMILY SIZE
D26: TOTAL | G26: =SUM(G25:G25) | H26: =SUM(H25:H25) | I26: =SUM(I25:I25) | J26: =SUM(J25:J25) | K26: =SUM(K25:K25) | L26: =SUM(L25:L25) | M26: =SUM(M25:M25) | N26: =SUM(N25:N25) | ... S26: =SUM(S25:S25) | U26: =SUM(U25:U25) | V26: =SUM(V25:V25) | W26: =SUM(W25:W25) | X26: =SUM(X25:X25) | Y26: =SUM(Y25:Y25) | Z26: =SUM(Z25:Z25) | AA26: =SUM(AA25:AA25) | AB26: =SUM(AB25:AB25) | ... AF26: =SUM(AF25:AF25) | AH26: BREW MAGIC | AI26: BREW MAGIC
D27: Excess Order | H27: =IFERROR(IF(ROUND(H26-$G26,3)>0,ROUND(H26-$G26,3),""),"") | I27: =IFERROR(IF(ROUND(I26-$G26,3)>0,ROUND(I26-$G26,3),""),"") | J27: =IFERROR(IF(ROUND(J26-$G26,3)>0,ROUND(J26-$G26,3),""),"") | K27: =IFERROR(IF(ROUND(K26-$G26,3)>0,ROUND(K26-$G26,3),""),"") | L27: =IFERROR(IF(ROUND(L26-$G26,3)>0,ROUND(L26-$G26,3),""),"") | M27: =IFERROR(IF(ROUND(M26-$G26,3)>0,ROUND(M26-$G26,3),""),"") | N27: =IFERROR(IF(ROUND(N26-$G26,3)>0,ROUND(N26-$G26,3),""),"") | O27: =IFERROR(IF(ROUND(O26-$G26,3)>0,ROUND(O26-$G26,3),""),"") | ... S27: =IFERROR(IF(ROUND(S26-$G26,3)>0,ROUND(S26-$G26,3),""),"") | U27: =IFERROR(IF(ROUND(U26-$G26,3)>0,ROUND(U26-$G26,3),""),"") | V27: =IFERROR(IF(ROUND(V26-$G26,3)>0,ROUND(V26-$G26,3),""),"") | W27: =IFERROR(IF(ROUND(W26-$G26,3)>0,ROUND(W26-$G26,3),""),"") | X27: =IFERROR(IF(ROUND(X26-$G26,3)>0,ROUND(X26-$G26,3),""),"") | Y27: =IFERROR(IF(ROUND(Y26-$G26,3)>0,ROUND(Y26-$G26,3),""),"") | Z27: =IFERROR(IF(ROUND(Z26-$G26,3)>0,ROUND(Z26-$G26,3),""),"") | AA27: =IFERROR(IF(ROUND(AA26-$G26,3)>0,ROUND(AA26-$G26,3),""),"") | AB27: =IFERROR(IF(ROUND(AB26-$G26,3)>0,ROUND(AB26-$G26,3),""),"") | ... AF27: =IFERROR(IF(ROUND(AF26-$G26,3)>0,ROUND(AF26-$G26,3),""),"") | AH27: UNIVERSAL POT BAG | AI27: UNIVERSAL POT BAG
D28: Short Order | H28: =IFERROR(IF(ROUND($G26-H26,3)>0,ROUND($G26-H26,3),""),"") | I28: =IFERROR(IF(ROUND($G26-I26,3)>0,ROUND($G26-I26,3),""),"") | J28: =IFERROR(IF(ROUND($G26-J26,3)>0,ROUND($G26-J26,3),""),"") | K28: =IFERROR(IF(ROUND($G26-K26,3)>0,ROUND($G26-K26,3),""),"") | L28: =IFERROR(IF(ROUND($G26-L26,3)>0,ROUND($G26-L26,3),""),"") | M28: =IFERROR(IF(ROUND($G26-M26,3)>0,ROUND($G26-M26,3),""),"") | N28: =IFERROR(IF(ROUND($G26-N26,3)>0,ROUND($G26-N26,3),""),"") | O28: =IFERROR(IF(ROUND($G26-O26,3)>0,ROUND($G26-O26,3),""),"") | ... S28: =IFERROR(IF(ROUND($G26-S26,3)>0,ROUND($G26-S26,3),""),"") | U28: =IFERROR(IF(ROUND($G26-U26,3)>0,ROUND($G26-U26,3),""),"") | V28: =IFERROR(IF(ROUND($G26-V26,3)>0,ROUND($G26-V26,3),""),"") | W28: =IFERROR(IF(ROUND($G26-W26,3)>0,ROUND($G26-W26,3),""),"") | X28: =IFERROR(IF(ROUND($G26-X26,3)>0,ROUND($G26-X26,3),""),"") | Y28: =IFERROR(IF(ROUND($G26-Y26,3)>0,ROUND($G26-Y26,3),""),"") | Z28: =IFERROR(IF(ROUND($G26-Z26,3)>0,ROUND($G26-Z26,3),""),"") | AA28: =IFERROR(IF(ROUND($G26-AA26,3)>0,ROUND($G26-AA26,3),""),"") | AB28: =IFERROR(IF(ROUND($G26-AB26,3)>0,ROUND($G26-AB26,3),""),"") | ... AF28: =IFERROR(IF(ROUND($G26-AF26,3)>0,ROUND($G26-AF26,3),""),"") | AH28: UNIVERSAL TWIN BAG | AI28: UNIVERSAL TWIN BAG
B29: USA | C29: TREE HOUSE | D29: CONSTANTA FAMILY SIZE | E29: 2 | F29: 0 | G29: =IFERROR(IF(OR($F29=0,VLOOKUP($D29,'MC MASTER'!$A:$R,18,0)=0),"-",ROUND(VLOOKUP($D29,'MC MASTER'!$A:$R,18,0)*$E29*$F29,3)),"-") | H29: =IFERROR(SUMIFS(WORKING!$Y:$Y,WORKING!$X:$X,$D29,WORKING!$W:$W,H$500),"") | I29: =IFERROR(SUMIFS(WORKING!$Y:$Y,WORKING!$X:$X,$D29,WORKING!$W:$W,I$500),"") | J29: =IFERROR(SUMIFS(WORKING!$Y:$Y,WORKING!$X:$X,$D29,WORKING!$W:$W,J$500),"") | K29: =IFERROR(SUMIFS(WORKING!$Y:$Y,WORKING!$X:$X,$D29,WORKING!$W:$W,K$500),"") | L29: =IFERROR(SUMIFS(WORKING!$Y:$Y,WORKING!$X:$X,$D29,WORKING!$W:$W,L$500),"") | M29: =IFERROR(SUMIFS(WORKING!$Y:$Y,WORKING!$X:$X,$D29,WORKING!$W:$W,M$500),"") | N29: =IFERROR(SUMIFS(WORKING!$Y:$Y,WORKING!$X:$X,$D29,WORKING!$W:$W,N$500),"") | O29: =IFERROR(SUMIFS(WORKING!$Y:$Y,WORKING!$X:$X,$D29,WORKING!$W:$W,O$500),"") | ... S29: =IFERROR(SUMIFS(WORKING!$Y:$Y,WORKING!$X:$X,$D29,WORKING!$W:$W,S$500),"") | U29: =IFERROR(SUMIFS(WORKING!$Z:$Z,WORKING!$X:$X,$D29,WORKING!$W:$W,H$500),"") | V29: =IFERROR(SUMIFS(WORKING!$Z:$Z,WORKING!$X:$X,$D29,WORKING!$W:$W,I$500),"") | W29: =IFERROR(SUMIFS(WORKING!$Z:$Z,WORKING!$X:$X,$D29,WORKING!$W:$W,J$500),"") | X29: =IFERROR(SUMIFS(WORKING!$Z:$Z,WORKING!$X:$X,$D29,WORKING!$W:$W,K$500),"") | Y29: =IFERROR(SUMIFS(WORKING!$Z:$Z,WORKING!$X:$X,$D29,WORKING!$W:$W,L$500),"") | Z29: =IFERROR(SUMIFS(WORKING!$Z:$Z,WORKING!$X:$X,$D29,WORKING!$W:$W,M$500),"") | AA29: =IFERROR(SUMIFS(WORKING!$Z:$Z,WORKING!$X:$X,$D29,WORKING!$W:$W,N$500),"") | AB29: =IFERROR(SUMIFS(WORKING!$Z:$Z,WORKING!$X:$X,$D29,WORKING!$W:$W,O$500),"") | ... AF29: =IFERROR(SUMIFS(WORKING!$Z:$Z,WORKING!$X:$X,$D29,WORKING!$W:$W,S$500),"") | AH29: PEARL PACK-PREMIX | AI29: PEARL PACK-PREMIX
D30: PERFACTA TAG | E30: 2 | F30: 1 | G30: =IFERROR(IF(OR($F30=0,VLOOKUP($D30,'MC MASTER'!$A:$R,18,0)=0),"-",ROUND(VLOOKUP($D30,'MC MASTER'!$A:$R,18,0)*$E30*$F30,3)),"-") | H30: =IFERROR(SUMIFS(WORKING!$Y:$Y,WORKING!$X:$X,$D30,WORKING!$W:$W,H$500),"") | I30: =IFERROR(SUMIFS(WORKING!$Y:$Y,WORKING!$X:$X,$D30,WORKING!$W:$W,I$500),"") | J30: =IFERROR(SUMIFS(WORKING!$Y:$Y,WORKING!$X:$X,$D30,WORKING!$W:$W,J$500),"") | K30: =IFERROR(SUMIFS(WORKING!$Y:$Y,WORKING!$X:$X,$D30,WORKING!$W:$W,K$500),"") | L30: =IFERROR(SUMIFS(WORKING!$Y:$Y,WORKING!$X:$X,$D30,WORKING!$W:$W,L$500),"") | M30: =IFERROR(SUMIFS(WORKING!$Y:$Y,WORKING!$X:$X,$D30,WORKING!$W:$W,M$500),"") | N30: =IFERROR(SUMIFS(WORKING!$Y:$Y,WORKING!$X:$X,$D30,WORKING!$W:$W,N$500),"") | O30: =IFERROR(SUMIFS(WORKING!$Y:$Y,WORKING!$X:$X,$D30,WORKING!$W:$W,O$500),"") | ... S30: =IFERROR(SUMIFS(WORKING!$Y:$Y,WORKING!$X:$X,$D30,WORKING!$W:$W,S$500),"") | U30: =IFERROR(SUMIFS(WORKING!$Z:$Z,WORKING!$X:$X,$D30,WORKING!$W:$W,H$500),"") | V30: =IFERROR(SUMIFS(WORKING!$Z:$Z,WORKING!$X:$X,$D30,WORKING!$W:$W,I$500),"") | W30: =IFERROR(SUMIFS(WORKING!$Z:$Z,WORKING!$X:$X,$D30,WORKING!$W:$W,J$500),"") | X30: =IFERROR(SUMIFS(WORKING!$Z:$Z,WORKING!$X:$X,$D30,WORKING!$W:$W,K$500),"") | Y30: =IFERROR(SUMIFS(WORKING!$Z:$Z,WORKING!$X:$X,$D30,WORKING!$W:$W,L$500),"") | Z30: =IFERROR(SUMIFS(WORKING!$Z:$Z,WORKING!$X:$X,$D30,WORKING!$W:$W,M$500),"") | AA30: =IFERROR(SUMIFS(WORKING!$Z:$Z,WORKING!$X:$X,$D30,WORKING!$W:$W,N$500),"") | AB30: =IFERROR(SUMIFS(WORKING!$Z:$Z,WORKING!$X:$X,$D30,WORKING!$W:$W,O$500),"") | ... AF30: =IFERROR(SUMIFS(WORKING!$Z:$Z,WORKING!$X:$X,$D30,WORKING!$W:$W,S$500),"") | AH30: PEARL PACK-PREMIX 2 | AI30: PEARL PACK-PREMIX
D31: TOTAL | G31: =SUM(G29:G30) | H31: =SUM(H29:H30) | I31: =SUM(I29:I30) | J31: =SUM(J29:J30) | K31: =SUM(K29:K30) | L31: =SUM(L29:L30) | M31: =SUM(M29:M30) | N31: =SUM(N29:N30) | ... S31: =SUM(S29:S30) | U31: =SUM(U29:U30) | V31: =SUM(V29:V30) | W31: =SUM(W29:W30) | X31: =SUM(X29:X30) | Y31: =SUM(Y29:Y30) | Z31: =SUM(Z29:Z30) | AA31: =SUM(AA29:AA30) | AB31: =SUM(AB29:AB30) | ... AF31: =SUM(AF29:AF30) | AH31: INSTANT COFFEE STICK PACK | AI31: INSTANT COFFEE STICK PACK
D32: Excess Order | H32: =IFERROR(IF(ROUND(H31-$G31,3)>0,ROUND(H31-$G31,3),""),"") | I32: =IFERROR(IF(ROUND(I31-$G31,3)>0,ROUND(I31-$G31,3),""),"") | J32: =IFERROR(IF(ROUND(J31-$G31,3)>0,ROUND(J31-$G31,3),""),"") | K32: =IFERROR(IF(ROUND(K31-$G31,3)>0,ROUND(K31-$G31,3),""),"") | L32: =IFERROR(IF(ROUND(L31-$G31,3)>0,ROUND(L31-$G31,3),""),"") | M32: =IFERROR(IF(ROUND(M31-$G31,3)>0,ROUND(M31-$G31,3),""),"") | N32: =IFERROR(IF(ROUND(N31-$G31,3)>0,ROUND(N31-$G31,3),""),"") | O32: =IFERROR(IF(ROUND(O31-$G31,3)>0,ROUND(O31-$G31,3),""),"") | ... S32: =IFERROR(IF(ROUND(S31-$G31,3)>0,ROUND(S31-$G31,3),""),"") | U32: =IFERROR(IF(ROUND(U31-$G31,3)>0,ROUND(U31-$G31,3),""),"") | V32: =IFERROR(IF(ROUND(V31-$G31,3)>0,ROUND(V31-$G31,3),""),"") | W32: =IFERROR(IF(ROUND(W31-$G31,3)>0,ROUND(W31-$G31,3),""),"") | X32: =IFERROR(IF(ROUND(X31-$G31,3)>0,ROUND(X31-$G31,3),""),"") | Y32: =IFERROR(IF(ROUND(Y31-$G31,3)>0,ROUND(Y31-$G31,3),""),"") | Z32: =IFERROR(IF(ROUND(Z31-$G31,3)>0,ROUND(Z31-$G31,3),""),"") | AA32: =IFERROR(IF(ROUND(AA31-$G31,3)>0,ROUND(AA31-$G31,3),""),"") | AB32: =IFERROR(IF(ROUND(AB31-$G31,3)>0,ROUND(AB31-$G31,3),""),"") | ... AF32: =IFERROR(IF(ROUND(AF31-$G31,3)>0,ROUND(AF31-$G31,3),""),"") | AH32: Instant Tea | AI32: Instant Tea
D33: Short Order | H33: =IFERROR(IF(ROUND($G31-H31,3)>0,ROUND($G31-H31,3),""),"") | I33: =IFERROR(IF(ROUND($G31-I31,3)>0,ROUND($G31-I31,3),""),"") | J33: =IFERROR(IF(ROUND($G31-J31,3)>0,ROUND($G31-J31,3),""),"") | K33: =IFERROR(IF(ROUND($G31-K31,3)>0,ROUND($G31-K31,3),""),"") | L33: =IFERROR(IF(ROUND($G31-L31,3)>0,ROUND($G31-L31,3),""),"") | M33: =IFERROR(IF(ROUND($G31-M31,3)>0,ROUND($G31-M31,3),""),"") | N33: =IFERROR(IF(ROUND($G31-N31,3)>0,ROUND($G31-N31,3),""),"") | O33: =IFERROR(IF(ROUND($G31-O31,3)>0,ROUND($G31-O31,3),""),"") | ... S33: =IFERROR(IF(ROUND($G31-S31,3)>0,ROUND($G31-S31,3),""),"") | U33: =IFERROR(IF(ROUND($G31-U31,3)>0,ROUND($G31-U31,3),""),"") | V33: =IFERROR(IF(ROUND($G31-V31,3)>0,ROUND($G31-V31,3),""),"") | W33: =IFERROR(IF(ROUND($G31-W31,3)>0,ROUND($G31-W31,3),""),"") | X33: =IFERROR(IF(ROUND($G31-X31,3)>0,ROUND($G31-X31,3),""),"") | Y33: =IFERROR(IF(ROUND($G31-Y31,3)>0,ROUND($G31-Y31,3),""),"") | Z33: =IFERROR(IF(ROUND($G31-Z31,3)>0,ROUND($G31-Z31,3),""),"") | AA33: =IFERROR(IF(ROUND($G31-AA31,3)>0,ROUND($G31-AA31,3),""),"") | AB33: =IFERROR(IF(ROUND($G31-AB31,3)>0,ROUND($G31-AB31,3),""),"") | ... AF33: =IFERROR(IF(ROUND($G31-AF31,3)>0,ROUND($G31-AF31,3),""),"") | AH33: VIKING-MULTITRACK | AI33: VIKING-MULTITRACK
A34: Zone 2 | B34: AFRICA | C34: SC | D34: MAISA TAGLESS | E34: 7 | F34: 1 | G34: =IFERROR(IF(OR($F34=0,VLOOKUP($D34,'MC MASTER'!$A:$R,18,0)=0),"-",ROUND(VLOOKUP($D34,'MC MASTER'!$A:$R,18,0)*$E34*$F34,3)),"-") | H34: =IFERROR(SUMIFS(WORKING!$Y:$Y,WORKING!$X:$X,$D34,WORKING!$W:$W,H$500),"") | I34: =IFERROR(SUMIFS(WORKING!$Y:$Y,WORKING!$X:$X,$D34,WORKING!$W:$W,I$500),"") | J34: =IFERROR(SUMIFS(WORKING!$Y:$Y,WORKING!$X:$X,$D34,WORKING!$W:$W,J$500),"") | K34: =IFERROR(SUMIFS(WORKING!$Y:$Y,WORKING!$X:$X,$D34,WORKING!$W:$W,K$500),"") | L34: =IFERROR(SUMIFS(WORKING!$Y:$Y,WORKING!$X:$X,$D34,WORKING!$W:$W,L$500),"") | M34: =IFERROR(SUMIFS(WORKING!$Y:$Y,WORKING!$X:$X,$D34,WORKING!$W:$W,M$500),"") | N34: =IFERROR(SUMIFS(WORKING!$Y:$Y,WORKING!$X:$X,$D34,WORKING!$W:$W,N$500),"") | O34: =IFERROR(SUMIFS(WORKING!$Y:$Y,WORKING!$X:$X,$D34,WORKING!$W:$W,O$500),"") | ... S34: =IFERROR(SUMIFS(WORKING!$Y:$Y,WORKING!$X:$X,$D34,WORKING!$W:$W,S$500),"") | U34: =IFERROR(SUMIFS(WORKING!$Z:$Z,WORKING!$X:$X,$D34,WORKING!$W:$W,H$500),"") | V34: =IFERROR(SUMIFS(WORKING!$Z:$Z,WORKING!$X:$X,$D34,WORKING!$W:$W,I$500),"") | W34: =IFERROR(SUMIFS(WORKING!$Z:$Z,WORKING!$X:$X,$D34,WORKING!$W:$W,J$500),"") | X34: =IFERROR(SUMIFS(WORKING!$Z:$Z,WORKING!$X:$X,$D34,WORKING!$W:$W,K$500),"") | Y34: =IFERROR(SUMIFS(WORKING!$Z:$Z,WORKING!$X:$X,$D34,WORKING!$W:$W,L$500),"") | Z34: =IFERROR(SUMIFS(WORKING!$Z:$Z,WORKING!$X:$X,$D34,WORKING!$W:$W,M$500),"") | AA34: =IFERROR(SUMIFS(WORKING!$Z:$Z,WORKING!$X:$X,$D34,WORKING!$W:$W,N$500),"") | AB34: =IFERROR(SUMIFS(WORKING!$Z:$Z,WORKING!$X:$X,$D34,WORKING!$W:$W,O$500),"") | ... AF34: =IFERROR(SUMIFS(WORKING!$Z:$Z,WORKING!$X:$X,$D34,WORKING!$W:$W,S$500),"") | AH34: Pearl Pack-FFS POUCH | AI34: Pearl Pack-FFS POUCH
D35: TOTAL | G35: =SUM(G34:G34) | H35: =SUM(H34:H34) | I35: =SUM(I34:I34) | J35: =SUM(J34:J34) | K35: =SUM(K34:K34) | L35: =SUM(L34:L34) | M35: =SUM(M34:M34) | N35: =SUM(N34:N34) | ... S35: =SUM(S34:S34) | U35: =SUM(U34:U34) | V35: =SUM(V34:V34) | W35: =SUM(W34:W34) | X35: =SUM(X34:X34) | Y35: =SUM(Y34:Y34) | Z35: =SUM(Z34:Z34) | AA35: =SUM(AA34:AA34) | AB35: =SUM(AB34:AB34) | ... AF35: =SUM(AF34:AF34) | AH35: PEARL PACK-NANO | AI35: PEARL PACK-NANO
D36: Excess Order | H36: =IFERROR(IF(ROUND(H35-$G35,3)>0,ROUND(H35-$G35,3),""),"") | I36: =IFERROR(IF(ROUND(I35-$G35,3)>0,ROUND(I35-$G35,3),""),"") | J36: =IFERROR(IF(ROUND(J35-$G35,3)>0,ROUND(J35-$G35,3),""),"") | K36: =IFERROR(IF(ROUND(K35-$G35,3)>0,ROUND(K35-$G35,3),""),"") | L36: =IFERROR(IF(ROUND(L35-$G35,3)>0,ROUND(L35-$G35,3),""),"") | M36: =IFERROR(IF(ROUND(M35-$G35,3)>0,ROUND(M35-$G35,3),""),"") | N36: =IFERROR(IF(ROUND(N35-$G35,3)>0,ROUND(N35-$G35,3),""),"") | O36: =IFERROR(IF(ROUND(O35-$G35,3)>0,ROUND(O35-$G35,3),""),"") | ... S36: =IFERROR(IF(ROUND(S35-$G35,3)>0,ROUND(S35-$G35,3),""),"") | U36: =IFERROR(IF(ROUND(U35-$G35,3)>0,ROUND(U35-$G35,3),""),"") | V36: =IFERROR(IF(ROUND(V35-$G35,3)>0,ROUND(V35-$G35,3),""),"") | W36: =IFERROR(IF(ROUND(W35-$G35,3)>0,ROUND(W35-$G35,3),""),"") | X36: =IFERROR(IF(ROUND(X35-$G35,3)>0,ROUND(X35-$G35,3),""),"") | Y36: =IFERROR(IF(ROUND(Y35-$G35,3)>0,ROUND(Y35-$G35,3),""),"") | Z36: =IFERROR(IF(ROUND(Z35-$G35,3)>0,ROUND(Z35-$G35,3),""),"") | AA36: =IFERROR(IF(ROUND(AA35-$G35,3)>0,ROUND(AA35-$G35,3),""),"") | AB36: =IFERROR(IF(ROUND(AB35-$G35,3)>0,ROUND(AB35-$G35,3),""),"") | ... AF36: =IFERROR(IF(ROUND(AF35-$G35,3)>0,ROUND(AF35-$G35,3),""),"") | AH36: VARIETIES PACK | AI36: VARIETIES PACK
D37: Short Order | H37: =IFERROR(IF(ROUND($G35-H35,3)>0,ROUND($G35-H35,3),""),"") | I37: =IFERROR(IF(ROUND($G35-I35,3)>0,ROUND($G35-I35,3),""),"") | J37: =IFERROR(IF(ROUND($G35-J35,3)>0,ROUND($G35-J35,3),""),"") | K37: =IFERROR(IF(ROUND($G35-K35,3)>0,ROUND($G35-K35,3),""),"") | L37: =IFERROR(IF(ROUND($G35-L35,3)>0,ROUND($G35-L35,3),""),"") | M37: =IFERROR(IF(ROUND($G35-M35,3)>0,ROUND($G35-M35,3),""),"") | N37: =IFERROR(IF(ROUND($G35-N35,3)>0,ROUND($G35-N35,3),""),"") | O37: =IFERROR(IF(ROUND($G35-O35,3)>0,ROUND($G35-O35,3),""),"") | ... S37: =IFERROR(IF(ROUND($G35-S35,3)>0,ROUND($G35-S35,3),""),"") | U37: =IFERROR(IF(ROUND($G35-U35,3)>0,ROUND($G35-U35,3),""),"") | V37: =IFERROR(IF(ROUND($G35-V35,3)>0,ROUND($G35-V35,3),""),"") | W37: =IFERROR(IF(ROUND($G35-W35,3)>0,ROUND($G35-W35,3),""),"") | X37: =IFERROR(IF(ROUND($G35-X35,3)>0,ROUND($G35-X35,3),""),"") | Y37: =IFERROR(IF(ROUND($G35-Y35,3)>0,ROUND($G35-Y35,3),""),"") | Z37: =IFERROR(IF(ROUND($G35-Z35,3)>0,ROUND($G35-Z35,3),""),"") | AA37: =IFERROR(IF(ROUND($G35-AA35,3)>0,ROUND($G35-AA35,3),""),"") | AB37: =IFERROR(IF(ROUND($G35-AB35,3)>0,ROUND($G35-AB35,3),""),"") | ... AF37: =IFERROR(IF(ROUND($G35-AF35,3)>0,ROUND($G35-AF35,3),""),"") | AH37: PERFECTA ENV | AI37: PERFECTA ENV
B38: EUROPE | C38: SC | D38: UNIVERSAL POT BAG | E38: 1 | F38: 0 | G38: =IFERROR(IF(OR($F38=0,VLOOKUP($D38,'MC MASTER'!$A:$R,18,0)=0),"-",ROUND(VLOOKUP($D38,'MC MASTER'!$A:$R,18,0)*$E38*$F38,3)),"-") | H38: =IFERROR(SUMIFS(WORKING!$Y:$Y,WORKING!$X:$X,$D38,WORKING!$W:$W,H$500),"") | I38: =IFERROR(SUMIFS(WORKING!$Y:$Y,WORKING!$X:$X,$D38,WORKING!$W:$W,I$500),"") | J38: =IFERROR(SUMIFS(WORKING!$Y:$Y,WORKING!$X:$X,$D38,WORKING!$W:$W,J$500),"") | K38: =IFERROR(SUMIFS(WORKING!$Y:$Y,WORKING!$X:$X,$D38,WORKING!$W:$W,K$500),"") | L38: =IFERROR(SUMIFS(WORKING!$Y:$Y,WORKING!$X:$X,$D38,WORKING!$W:$W,L$500),"") | M38: =IFERROR(SUMIFS(WORKING!$Y:$Y,WORKING!$X:$X,$D38,WORKING!$W:$W,M$500),"") | N38: =IFERROR(SUMIFS(WORKING!$Y:$Y,WORKING!$X:$X,$D38,WORKING!$W:$W,N$500),"") | O38: =IFERROR(SUMIFS(WORKING!$Y:$Y,WORKING!$X:$X,$D38,WORKING!$W:$W,O$500),"") | ... S38: =IFERROR(SUMIFS(WORKING!$Y:$Y,WORKING!$X:$X,$D38,WORKING!$W:$W,S$500),"") | U38: =IFERROR(SUMIFS(WORKING!$Z:$Z,WORKING!$X:$X,$D38,WORKING!$W:$W,H$500),"") | V38: =IFERROR(SUMIFS(WORKING!$Z:$Z,WORKING!$X:$X,$D38,WORKING!$W:$W,I$500),"") | W38: =IFERROR(SUMIFS(WORKING!$Z:$Z,WORKING!$X:$X,$D38,WORKING!$W:$W,J$500),"") | X38: =IFERROR(SUMIFS(WORKING!$Z:$Z,WORKING!$X:$X,$D38,WORKING!$W:$W,K$500),"") | Y38: =IFERROR(SUMIFS(WORKING!$Z:$Z,WORKING!$X:$X,$D38,WORKING!$W:$W,L$500),"") | Z38: =IFERROR(SUMIFS(WORKING!$Z:$Z,WORKING!$X:$X,$D38,WORKING!$W:$W,M$500),"") | AA38: =IFERROR(SUMIFS(WORKING!$Z:$Z,WORKING!$X:$X,$D38,WORKING!$W:$W,N$500),"") | AB38: =IFERROR(SUMIFS(WORKING!$Z:$Z,WORKING!$X:$X,$D38,WORKING!$W:$W,O$500),"") | ... AF38: =IFERROR(SUMIFS(WORKING!$Z:$Z,WORKING!$X:$X,$D38,WORKING!$W:$W,S$500),"") | AH38: CONSTANTA TAG D | AI38: CONSTANTA TAG
